Internal Server Error: /
Traceback (most recent call last):
  File "C:\Users\bayro\AppData\Roaming\Python\Python310\site-packages\django\core\handlers\exception.py", line 55, in inner
    response = get_response(request)
  File "C:\Users\bayro\AppData\Roaming\Python\Python310\site-packages\django\core\handlers\base.py", line 197, in _get_response
    response = wrapped_callback(request, *callback_args, **callback_kwargs)
  File "C:\Users\bayro\Desktop\IngSoftware\career_roadmap\roadmap\views.py", line 7, in home
    return render(request, 'roadmap/index.html')
  File "C:\Users\bayro\AppData\Roaming\Python\Python310\site-packages\django\shortcuts.py", line 25, in render
    content = loader.render_to_string(template_name, context, request, using=using)
  File "C:\Users\bayro\AppData\Roaming\Python\Python310\site-packages\django\template\loader.py", line 62, in render_to_string
    return template.render(context, request)
  File "C:\Users\bayro\AppData\Roaming\Python\Python310\site-packages\django\template\backends\django.py", line 61, in render
    return self.template.render(context)
  File "C:\Users\bayro\AppData\Roaming\Python\Python310\site-packages\django\template\base.py", line 171, in render
    return self._render(context)
  File "C:\Users\bayro\AppData\Roaming\Python\Python310\site-packages\django\template\base.py", line 163, in _render
    return self.nodelist.render(context)
  File "C:\Users\bayro\AppData\Roaming\Python\Python310\site-packages\django\template\base.py", line 1000, in render
    return SafeString("".join([node.render_annotated(context) for node in self]))
  File "C:\Users\bayro\AppData\Roaming\Python\Python310\site-packages\django\template\base.py", line 1000, in <listcomp>
    return SafeString("".join([node.render_annotated(context) for node in self]))
  File "C:\Users\bayro\AppData\Roaming\Python\Python310\site-packages\django\template\base.py", line 961, in render_annotated
    return self.render(context)
  File "C:\Users\bayro\AppData\Roaming\Python\Python310\site-packages\django\template\loader_tags.py", line 159, in render
    return compiled_parent._render(context)
  File "C:\Users\bayro\AppData\Roaming\Python\Python310\site-packages\django\template\base.py", line 163, in _render
    return self.nodelist.render(context)
  File "C:\Users\bayro\AppData\Roaming\Python\Python310\site-packages\django\template\base.py", line 1000, in render
    return SafeString("".join([node.render_annotated(context) for node in self]))
  File "C:\Users\bayro\AppData\Roaming\Python\Python310\site-packages\django\template\base.py", line 1000, in <listcomp>
    return SafeString("".join([node.render_annotated(context) for node in self]))
  File "C:\Users\bayro\AppData\Roaming\Python\Python310\site-packages\django\template\base.py", line 961, in render_annotated
    return self.render(context)
  File "C:\Users\bayro\AppData\Roaming\Python\Python310\site-packages\django\template\defaulttags.py", line 479, in render
    url = reverse(view_name, args=args, kwargs=kwargs, current_app=current_app)
  File "C:\Users\bayro\AppData\Roaming\Python\Python310\site-packages\django\urls\base.py", line 88, in reverse
    return resolver._reverse_with_prefix(view, prefix, *args, **kwargs)
  File "C:\Users\bayro\AppData\Roaming\Python\Python310\site-packages\django\urls\resolvers.py", line 851, in _reverse_with_prefix
    raise NoReverseMatch(msg)
django.urls.exceptions.NoReverseMatch: Reverse for 'profile' not found. 'profile' is not a valid view function or pattern name.
Internal Server Error: /
Traceback (most recent call last):
  File "C:\Users\bayro\AppData\Roaming\Python\Python310\site-packages\django\core\handlers\exception.py", line 55, in inner
    response = get_response(request)
  File "C:\Users\bayro\AppData\Roaming\Python\Python310\site-packages\django\core\handlers\base.py", line 197, in _get_response
    response = wrapped_callback(request, *callback_args, **callback_kwargs)
  File "C:\Users\bayro\Desktop\IngSoftware\career_roadmap\roadmap\views.py", line 7, in home
    return render(request, 'roadmap/index.html')
  File "C:\Users\bayro\AppData\Roaming\Python\Python310\site-packages\django\shortcuts.py", line 25, in render
    content = loader.render_to_string(template_name, context, request, using=using)
  File "C:\Users\bayro\AppData\Roaming\Python\Python310\site-packages\django\template\loader.py", line 62, in render_to_string
    return template.render(context, request)
  File "C:\Users\bayro\AppData\Roaming\Python\Python310\site-packages\django\template\backends\django.py", line 61, in render
    return self.template.render(context)
  File "C:\Users\bayro\AppData\Roaming\Python\Python310\site-packages\django\template\base.py", line 171, in render
    return self._render(context)
  File "C:\Users\bayro\AppData\Roaming\Python\Python310\site-packages\django\template\base.py", line 163, in _render
    return self.nodelist.render(context)
  File "C:\Users\bayro\AppData\Roaming\Python\Python310\site-packages\django\template\base.py", line 1000, in render
    return SafeString("".join([node.render_annotated(context) for node in self]))
  File "C:\Users\bayro\AppData\Roaming\Python\Python310\site-packages\django\template\base.py", line 1000, in <listcomp>
    return SafeString("".join([node.render_annotated(context) for node in self]))
  File "C:\Users\bayro\AppData\Roaming\Python\Python310\site-packages\django\template\base.py", line 961, in render_annotated
    return self.render(context)
  File "C:\Users\bayro\AppData\Roaming\Python\Python310\site-packages\django\template\loader_tags.py", line 159, in render
    return compiled_parent._render(context)
  File "C:\Users\bayro\AppData\Roaming\Python\Python310\site-packages\django\template\base.py", line 163, in _render
    return self.nodelist.render(context)
  File "C:\Users\bayro\AppData\Roaming\Python\Python310\site-packages\django\template\base.py", line 1000, in render
    return SafeString("".join([node.render_annotated(context) for node in self]))
  File "C:\Users\bayro\AppData\Roaming\Python\Python310\site-packages\django\template\base.py", line 1000, in <listcomp>
    return SafeString("".join([node.render_annotated(context) for node in self]))
  File "C:\Users\bayro\AppData\Roaming\Python\Python310\site-packages\django\template\base.py", line 961, in render_annotated
    return self.render(context)
  File "C:\Users\bayro\AppData\Roaming\Python\Python310\site-packages\django\template\defaulttags.py", line 479, in render
    url = reverse(view_name, args=args, kwargs=kwargs, current_app=current_app)
  File "C:\Users\bayro\AppData\Roaming\Python\Python310\site-packages\django\urls\base.py", line 88, in reverse
    return resolver._reverse_with_prefix(view, prefix, *args, **kwargs)
  File "C:\Users\bayro\AppData\Roaming\Python\Python310\site-packages\django\urls\resolvers.py", line 851, in _reverse_with_prefix
    raise NoReverseMatch(msg)
django.urls.exceptions.NoReverseMatch: Reverse for 'profile' not found. 'profile' is not a valid view function or pattern name.
Internal Server Error: /chat/
Traceback (most recent call last):
  File "C:\Users\bayro\AppData\Roaming\Python\Python310\site-packages\django\core\handlers\exception.py", line 55, in inner
    response = get_response(request)
  File "C:\Users\bayro\AppData\Roaming\Python\Python310\site-packages\django\core\handlers\base.py", line 197, in _get_response
    response = wrapped_callback(request, *callback_args, **callback_kwargs)
  File "C:\Users\bayro\Desktop\IngSoftware\career_roadmap\roadmap\views.py", line 29, in chat
    return render(request, 'roadmap/chat.html')
  File "C:\Users\bayro\AppData\Roaming\Python\Python310\site-packages\django\shortcuts.py", line 25, in render
    content = loader.render_to_string(template_name, context, request, using=using)
  File "C:\Users\bayro\AppData\Roaming\Python\Python310\site-packages\django\template\loader.py", line 62, in render_to_string
    return template.render(context, request)
  File "C:\Users\bayro\AppData\Roaming\Python\Python310\site-packages\django\template\backends\django.py", line 61, in render
    return self.template.render(context)
  File "C:\Users\bayro\AppData\Roaming\Python\Python310\site-packages\django\template\base.py", line 171, in render
    return self._render(context)
  File "C:\Users\bayro\AppData\Roaming\Python\Python310\site-packages\django\template\base.py", line 163, in _render
    return self.nodelist.render(context)
  File "C:\Users\bayro\AppData\Roaming\Python\Python310\site-packages\django\template\base.py", line 1000, in render
    return SafeString("".join([node.render_annotated(context) for node in self]))
  File "C:\Users\bayro\AppData\Roaming\Python\Python310\site-packages\django\template\base.py", line 1000, in <listcomp>
    return SafeString("".join([node.render_annotated(context) for node in self]))
  File "C:\Users\bayro\AppData\Roaming\Python\Python310\site-packages\django\template\base.py", line 961, in render_annotated
    return self.render(context)
  File "C:\Users\bayro\AppData\Roaming\Python\Python310\site-packages\django\template\loader_tags.py", line 159, in render
    return compiled_parent._render(context)
  File "C:\Users\bayro\AppData\Roaming\Python\Python310\site-packages\django\template\base.py", line 163, in _render
    return self.nodelist.render(context)
  File "C:\Users\bayro\AppData\Roaming\Python\Python310\site-packages\django\template\base.py", line 1000, in render
    return SafeString("".join([node.render_annotated(context) for node in self]))
  File "C:\Users\bayro\AppData\Roaming\Python\Python310\site-packages\django\template\base.py", line 1000, in <listcomp>
    return SafeString("".join([node.render_annotated(context) for node in self]))
  File "C:\Users\bayro\AppData\Roaming\Python\Python310\site-packages\django\template\base.py", line 961, in render_annotated
    return self.render(context)
  File "C:\Users\bayro\AppData\Roaming\Python\Python310\site-packages\django\template\defaulttags.py", line 479, in render
    url = reverse(view_name, args=args, kwargs=kwargs, current_app=current_app)
  File "C:\Users\bayro\AppData\Roaming\Python\Python310\site-packages\django\urls\base.py", line 88, in reverse
    return resolver._reverse_with_prefix(view, prefix, *args, **kwargs)
  File "C:\Users\bayro\AppData\Roaming\Python\Python310\site-packages\django\urls\resolvers.py", line 851, in _reverse_with_prefix
    raise NoReverseMatch(msg)
django.urls.exceptions.NoReverseMatch: Reverse for 'profile' not found. 'profile' is not a valid view function or pattern name.
Internal Server Error: /
Traceback (most recent call last):
  File "C:\Users\bayro\AppData\Roaming\Python\Python310\site-packages\django\core\handlers\exception.py", line 55, in inner
    response = get_response(request)
  File "C:\Users\bayro\AppData\Roaming\Python\Python310\site-packages\django\core\handlers\base.py", line 197, in _get_response
    response = wrapped_callback(request, *callback_args, **callback_kwargs)
  File "C:\Users\bayro\Desktop\IngSoftware\career_roadmap\roadmap\views.py", line 7, in home
    return render(request, 'roadmap/index.html')
  File "C:\Users\bayro\AppData\Roaming\Python\Python310\site-packages\django\shortcuts.py", line 25, in render
    content = loader.render_to_string(template_name, context, request, using=using)
  File "C:\Users\bayro\AppData\Roaming\Python\Python310\site-packages\django\template\loader.py", line 62, in render_to_string
    return template.render(context, request)
  File "C:\Users\bayro\AppData\Roaming\Python\Python310\site-packages\django\template\backends\django.py", line 61, in render
    return self.template.render(context)
  File "C:\Users\bayro\AppData\Roaming\Python\Python310\site-packages\django\template\base.py", line 171, in render
    return self._render(context)
  File "C:\Users\bayro\AppData\Roaming\Python\Python310\site-packages\django\template\base.py", line 163, in _render
    return self.nodelist.render(context)
  File "C:\Users\bayro\AppData\Roaming\Python\Python310\site-packages\django\template\base.py", line 1000, in render
    return SafeString("".join([node.render_annotated(context) for node in self]))
  File "C:\Users\bayro\AppData\Roaming\Python\Python310\site-packages\django\template\base.py", line 1000, in <listcomp>
    return SafeString("".join([node.render_annotated(context) for node in self]))
  File "C:\Users\bayro\AppData\Roaming\Python\Python310\site-packages\django\template\base.py", line 961, in render_annotated
    return self.render(context)
  File "C:\Users\bayro\AppData\Roaming\Python\Python310\site-packages\django\template\loader_tags.py", line 159, in render
    return compiled_parent._render(context)
  File "C:\Users\bayro\AppData\Roaming\Python\Python310\site-packages\django\template\base.py", line 163, in _render
    return self.nodelist.render(context)
  File "C:\Users\bayro\AppData\Roaming\Python\Python310\site-packages\django\template\base.py", line 1000, in render
    return SafeString("".join([node.render_annotated(context) for node in self]))
  File "C:\Users\bayro\AppData\Roaming\Python\Python310\site-packages\django\template\base.py", line 1000, in <listcomp>
    return SafeString("".join([node.render_annotated(context) for node in self]))
  File "C:\Users\bayro\AppData\Roaming\Python\Python310\site-packages\django\template\base.py", line 961, in render_annotated
    return self.render(context)
  File "C:\Users\bayro\AppData\Roaming\Python\Python310\site-packages\django\template\defaulttags.py", line 479, in render
    url = reverse(view_name, args=args, kwargs=kwargs, current_app=current_app)
  File "C:\Users\bayro\AppData\Roaming\Python\Python310\site-packages\django\urls\base.py", line 88, in reverse
    return resolver._reverse_with_prefix(view, prefix, *args, **kwargs)
  File "C:\Users\bayro\AppData\Roaming\Python\Python310\site-packages\django\urls\resolvers.py", line 851, in _reverse_with_prefix
    raise NoReverseMatch(msg)
django.urls.exceptions.NoReverseMatch: Reverse for 'profile' not found. 'profile' is not a valid view function or pattern name.
Internal Server Error: /chat/
Traceback (most recent call last):
  File "C:\Users\bayro\AppData\Roaming\Python\Python310\site-packages\django\db\backends\utils.py", line 105, in _execute
    return self.cursor.execute(sql, params)
  File "C:\Users\bayro\AppData\Roaming\Python\Python310\site-packages\django\db\backends\sqlite3\base.py", line 329, in execute
    return super().execute(query, params)
sqlite3.OperationalError: table roadmap_user has no column named chat_history

The above exception was the direct cause of the following exception:

Traceback (most recent call last):
  File "C:\Users\bayro\AppData\Roaming\Python\Python310\site-packages\django\core\handlers\exception.py", line 55, in inner
    response = get_response(request)
  File "C:\Users\bayro\AppData\Roaming\Python\Python310\site-packages\django\core\handlers\base.py", line 197, in _get_response
    response = wrapped_callback(request, *callback_args, **callback_kwargs)
  File "C:\Users\bayro\Desktop\IngSoftware\career_roadmap\roadmap\views.py", line 15, in chat
    user = User.objects.create()
  File "C:\Users\bayro\AppData\Roaming\Python\Python310\site-packages\django\db\models\manager.py", line 87, in manager_method
    return getattr(self.get_queryset(), name)(*args, **kwargs)
  File "C:\Users\bayro\AppData\Roaming\Python\Python310\site-packages\django\db\models\query.py", line 679, in create
    obj.save(force_insert=True, using=self.db)
  File "C:\Users\bayro\AppData\Roaming\Python\Python310\site-packages\django\db\models\base.py", line 822, in save
    self.save_base(
  File "C:\Users\bayro\AppData\Roaming\Python\Python310\site-packages\django\db\models\base.py", line 909, in save_base
    updated = self._save_table(
  File "C:\Users\bayro\AppData\Roaming\Python\Python310\site-packages\django\db\models\base.py", line 1071, in _save_table
    results = self._do_insert(
  File "C:\Users\bayro\AppData\Roaming\Python\Python310\site-packages\django\db\models\base.py", line 1112, in _do_insert
    return manager._insert(
  File "C:\Users\bayro\AppData\Roaming\Python\Python310\site-packages\django\db\models\manager.py", line 87, in manager_method
    return getattr(self.get_queryset(), name)(*args, **kwargs)
  File "C:\Users\bayro\AppData\Roaming\Python\Python310\site-packages\django\db\models\query.py", line 1847, in _insert
    return query.get_compiler(using=using).execute_sql(returning_fields)
  File "C:\Users\bayro\AppData\Roaming\Python\Python310\site-packages\django\db\models\sql\compiler.py", line 1823, in execute_sql
    cursor.execute(sql, params)
  File "C:\Users\bayro\AppData\Roaming\Python\Python310\site-packages\django\db\backends\utils.py", line 122, in execute
    return super().execute(sql, params)
  File "C:\Users\bayro\AppData\Roaming\Python\Python310\site-packages\django\db\backends\utils.py", line 79, in execute
    return self._execute_with_wrappers(
  File "C:\Users\bayro\AppData\Roaming\Python\Python310\site-packages\django\db\backends\utils.py", line 92, in _execute_with_wrappers
    return executor(sql, params, many, context)
  File "C:\Users\bayro\AppData\Roaming\Python\Python310\site-packages\django\db\backends\utils.py", line 100, in _execute
    with self.db.wrap_database_errors:
  File "C:\Users\bayro\AppData\Roaming\Python\Python310\site-packages\django\db\utils.py", line 91, in __exit__
    raise dj_exc_value.with_traceback(traceback) from exc_value
  File "C:\Users\bayro\AppData\Roaming\Python\Python310\site-packages\django\db\backends\utils.py", line 105, in _execute
    return self.cursor.execute(sql, params)
  File "C:\Users\bayro\AppData\Roaming\Python\Python310\site-packages\django\db\backends\sqlite3\base.py", line 329, in execute
    return super().execute(query, params)
django.db.utils.OperationalError: table roadmap_user has no column named chat_history
Internal Server Error: /chat/
Traceback (most recent call last):
  File "C:\Users\bayro\AppData\Roaming\Python\Python310\site-packages\django\db\backends\utils.py", line 105, in _execute
    return self.cursor.execute(sql, params)
  File "C:\Users\bayro\AppData\Roaming\Python\Python310\site-packages\django\db\backends\sqlite3\base.py", line 329, in execute
    return super().execute(query, params)
sqlite3.OperationalError: table roadmap_user has no column named chat_history

The above exception was the direct cause of the following exception:

Traceback (most recent call last):
  File "C:\Users\bayro\AppData\Roaming\Python\Python310\site-packages\django\core\handlers\exception.py", line 55, in inner
    response = get_response(request)
  File "C:\Users\bayro\AppData\Roaming\Python\Python310\site-packages\django\core\handlers\base.py", line 197, in _get_response
    response = wrapped_callback(request, *callback_args, **callback_kwargs)
  File "C:\Users\bayro\Desktop\IngSoftware\career_roadmap\roadmap\views.py", line 15, in chat
    user = User.objects.create()
  File "C:\Users\bayro\AppData\Roaming\Python\Python310\site-packages\django\db\models\manager.py", line 87, in manager_method
    return getattr(self.get_queryset(), name)(*args, **kwargs)
  File "C:\Users\bayro\AppData\Roaming\Python\Python310\site-packages\django\db\models\query.py", line 679, in create
    obj.save(force_insert=True, using=self.db)
  File "C:\Users\bayro\AppData\Roaming\Python\Python310\site-packages\django\db\models\base.py", line 822, in save
    self.save_base(
  File "C:\Users\bayro\AppData\Roaming\Python\Python310\site-packages\django\db\models\base.py", line 909, in save_base
    updated = self._save_table(
  File "C:\Users\bayro\AppData\Roaming\Python\Python310\site-packages\django\db\models\base.py", line 1071, in _save_table
    results = self._do_insert(
  File "C:\Users\bayro\AppData\Roaming\Python\Python310\site-packages\django\db\models\base.py", line 1112, in _do_insert
    return manager._insert(
  File "C:\Users\bayro\AppData\Roaming\Python\Python310\site-packages\django\db\models\manager.py", line 87, in manager_method
    return getattr(self.get_queryset(), name)(*args, **kwargs)
  File "C:\Users\bayro\AppData\Roaming\Python\Python310\site-packages\django\db\models\query.py", line 1847, in _insert
    return query.get_compiler(using=using).execute_sql(returning_fields)
  File "C:\Users\bayro\AppData\Roaming\Python\Python310\site-packages\django\db\models\sql\compiler.py", line 1823, in execute_sql
    cursor.execute(sql, params)
  File "C:\Users\bayro\AppData\Roaming\Python\Python310\site-packages\django\db\backends\utils.py", line 122, in execute
    return super().execute(sql, params)
  File "C:\Users\bayro\AppData\Roaming\Python\Python310\site-packages\django\db\backends\utils.py", line 79, in execute
    return self._execute_with_wrappers(
  File "C:\Users\bayro\AppData\Roaming\Python\Python310\site-packages\django\db\backends\utils.py", line 92, in _execute_with_wrappers
    return executor(sql, params, many, context)
  File "C:\Users\bayro\AppData\Roaming\Python\Python310\site-packages\django\db\backends\utils.py", line 100, in _execute
    with self.db.wrap_database_errors:
  File "C:\Users\bayro\AppData\Roaming\Python\Python310\site-packages\django\db\utils.py", line 91, in __exit__
    raise dj_exc_value.with_traceback(traceback) from exc_value
  File "C:\Users\bayro\AppData\Roaming\Python\Python310\site-packages\django\db\backends\utils.py", line 105, in _execute
    return self.cursor.execute(sql, params)
  File "C:\Users\bayro\AppData\Roaming\Python\Python310\site-packages\django\db\backends\sqlite3\base.py", line 329, in execute
    return super().execute(query, params)
django.db.utils.OperationalError: table roadmap_user has no column named chat_history
Internal Server Error: /chat/
Traceback (most recent call last):
  File "C:\Users\bayro\AppData\Roaming\Python\Python310\site-packages\django\db\backends\utils.py", line 105, in _execute
    return self.cursor.execute(sql, params)
  File "C:\Users\bayro\AppData\Roaming\Python\Python310\site-packages\django\db\backends\sqlite3\base.py", line 329, in execute
    return super().execute(query, params)
sqlite3.OperationalError: table roadmap_user has no column named chat_history

The above exception was the direct cause of the following exception:

Traceback (most recent call last):
  File "C:\Users\bayro\AppData\Roaming\Python\Python310\site-packages\django\core\handlers\exception.py", line 55, in inner
    response = get_response(request)
  File "C:\Users\bayro\AppData\Roaming\Python\Python310\site-packages\django\core\handlers\base.py", line 197, in _get_response
    response = wrapped_callback(request, *callback_args, **callback_kwargs)
  File "C:\Users\bayro\Desktop\IngSoftware\career_roadmap\roadmap\views.py", line 15, in chat
    user = User.objects.create()
  File "C:\Users\bayro\AppData\Roaming\Python\Python310\site-packages\django\db\models\manager.py", line 87, in manager_method
    return getattr(self.get_queryset(), name)(*args, **kwargs)
  File "C:\Users\bayro\AppData\Roaming\Python\Python310\site-packages\django\db\models\query.py", line 679, in create
    obj.save(force_insert=True, using=self.db)
  File "C:\Users\bayro\AppData\Roaming\Python\Python310\site-packages\django\db\models\base.py", line 822, in save
    self.save_base(
  File "C:\Users\bayro\AppData\Roaming\Python\Python310\site-packages\django\db\models\base.py", line 909, in save_base
    updated = self._save_table(
  File "C:\Users\bayro\AppData\Roaming\Python\Python310\site-packages\django\db\models\base.py", line 1071, in _save_table
    results = self._do_insert(
  File "C:\Users\bayro\AppData\Roaming\Python\Python310\site-packages\django\db\models\base.py", line 1112, in _do_insert
    return manager._insert(
  File "C:\Users\bayro\AppData\Roaming\Python\Python310\site-packages\django\db\models\manager.py", line 87, in manager_method
    return getattr(self.get_queryset(), name)(*args, **kwargs)
  File "C:\Users\bayro\AppData\Roaming\Python\Python310\site-packages\django\db\models\query.py", line 1847, in _insert
    return query.get_compiler(using=using).execute_sql(returning_fields)
  File "C:\Users\bayro\AppData\Roaming\Python\Python310\site-packages\django\db\models\sql\compiler.py", line 1823, in execute_sql
    cursor.execute(sql, params)
  File "C:\Users\bayro\AppData\Roaming\Python\Python310\site-packages\django\db\backends\utils.py", line 122, in execute
    return super().execute(sql, params)
  File "C:\Users\bayro\AppData\Roaming\Python\Python310\site-packages\django\db\backends\utils.py", line 79, in execute
    return self._execute_with_wrappers(
  File "C:\Users\bayro\AppData\Roaming\Python\Python310\site-packages\django\db\backends\utils.py", line 92, in _execute_with_wrappers
    return executor(sql, params, many, context)
  File "C:\Users\bayro\AppData\Roaming\Python\Python310\site-packages\django\db\backends\utils.py", line 100, in _execute
    with self.db.wrap_database_errors:
  File "C:\Users\bayro\AppData\Roaming\Python\Python310\site-packages\django\db\utils.py", line 91, in __exit__
    raise dj_exc_value.with_traceback(traceback) from exc_value
  File "C:\Users\bayro\AppData\Roaming\Python\Python310\site-packages\django\db\backends\utils.py", line 105, in _execute
    return self.cursor.execute(sql, params)
  File "C:\Users\bayro\AppData\Roaming\Python\Python310\site-packages\django\db\backends\sqlite3\base.py", line 329, in execute
    return super().execute(query, params)
django.db.utils.OperationalError: table roadmap_user has no column named chat_history
Internal Server Error: /chat/
Traceback (most recent call last):
  File "C:\Users\bayro\AppData\Roaming\Python\Python310\site-packages\django\db\backends\utils.py", line 105, in _execute
    return self.cursor.execute(sql, params)
  File "C:\Users\bayro\AppData\Roaming\Python\Python310\site-packages\django\db\backends\sqlite3\base.py", line 329, in execute
    return super().execute(query, params)
sqlite3.OperationalError: table roadmap_user has no column named chat_history

The above exception was the direct cause of the following exception:

Traceback (most recent call last):
  File "C:\Users\bayro\AppData\Roaming\Python\Python310\site-packages\django\core\handlers\exception.py", line 55, in inner
    response = get_response(request)
  File "C:\Users\bayro\AppData\Roaming\Python\Python310\site-packages\django\core\handlers\base.py", line 197, in _get_response
    response = wrapped_callback(request, *callback_args, **callback_kwargs)
  File "C:\Users\bayro\Desktop\IngSoftware\career_roadmap\roadmap\views.py", line 15, in chat
    user = User.objects.create()
  File "C:\Users\bayro\AppData\Roaming\Python\Python310\site-packages\django\db\models\manager.py", line 87, in manager_method
    return getattr(self.get_queryset(), name)(*args, **kwargs)
  File "C:\Users\bayro\AppData\Roaming\Python\Python310\site-packages\django\db\models\query.py", line 679, in create
    obj.save(force_insert=True, using=self.db)
  File "C:\Users\bayro\AppData\Roaming\Python\Python310\site-packages\django\db\models\base.py", line 822, in save
    self.save_base(
  File "C:\Users\bayro\AppData\Roaming\Python\Python310\site-packages\django\db\models\base.py", line 909, in save_base
    updated = self._save_table(
  File "C:\Users\bayro\AppData\Roaming\Python\Python310\site-packages\django\db\models\base.py", line 1071, in _save_table
    results = self._do_insert(
  File "C:\Users\bayro\AppData\Roaming\Python\Python310\site-packages\django\db\models\base.py", line 1112, in _do_insert
    return manager._insert(
  File "C:\Users\bayro\AppData\Roaming\Python\Python310\site-packages\django\db\models\manager.py", line 87, in manager_method
    return getattr(self.get_queryset(), name)(*args, **kwargs)
  File "C:\Users\bayro\AppData\Roaming\Python\Python310\site-packages\django\db\models\query.py", line 1847, in _insert
    return query.get_compiler(using=using).execute_sql(returning_fields)
  File "C:\Users\bayro\AppData\Roaming\Python\Python310\site-packages\django\db\models\sql\compiler.py", line 1823, in execute_sql
    cursor.execute(sql, params)
  File "C:\Users\bayro\AppData\Roaming\Python\Python310\site-packages\django\db\backends\utils.py", line 122, in execute
    return super().execute(sql, params)
  File "C:\Users\bayro\AppData\Roaming\Python\Python310\site-packages\django\db\backends\utils.py", line 79, in execute
    return self._execute_with_wrappers(
  File "C:\Users\bayro\AppData\Roaming\Python\Python310\site-packages\django\db\backends\utils.py", line 92, in _execute_with_wrappers
    return executor(sql, params, many, context)
  File "C:\Users\bayro\AppData\Roaming\Python\Python310\site-packages\django\db\backends\utils.py", line 100, in _execute
    with self.db.wrap_database_errors:
  File "C:\Users\bayro\AppData\Roaming\Python\Python310\site-packages\django\db\utils.py", line 91, in __exit__
    raise dj_exc_value.with_traceback(traceback) from exc_value
  File "C:\Users\bayro\AppData\Roaming\Python\Python310\site-packages\django\db\backends\utils.py", line 105, in _execute
    return self.cursor.execute(sql, params)
  File "C:\Users\bayro\AppData\Roaming\Python\Python310\site-packages\django\db\backends\sqlite3\base.py", line 329, in execute
    return super().execute(query, params)
django.db.utils.OperationalError: table roadmap_user has no column named chat_history
Internal Server Error: /chat/
Traceback (most recent call last):
  File "C:\Users\bayro\AppData\Roaming\Python\Python310\site-packages\django\db\backends\utils.py", line 105, in _execute
    return self.cursor.execute(sql, params)
  File "C:\Users\bayro\AppData\Roaming\Python\Python310\site-packages\django\db\backends\sqlite3\base.py", line 329, in execute
    return super().execute(query, params)
sqlite3.OperationalError: table roadmap_user has no column named chat_history

The above exception was the direct cause of the following exception:

Traceback (most recent call last):
  File "C:\Users\bayro\AppData\Roaming\Python\Python310\site-packages\django\core\handlers\exception.py", line 55, in inner
    response = get_response(request)
  File "C:\Users\bayro\AppData\Roaming\Python\Python310\site-packages\django\core\handlers\base.py", line 197, in _get_response
    response = wrapped_callback(request, *callback_args, **callback_kwargs)
  File "C:\Users\bayro\Desktop\IngSoftware\career_roadmap\roadmap\views.py", line 15, in chat
    user = User.objects.create()
  File "C:\Users\bayro\AppData\Roaming\Python\Python310\site-packages\django\db\models\manager.py", line 87, in manager_method
    return getattr(self.get_queryset(), name)(*args, **kwargs)
  File "C:\Users\bayro\AppData\Roaming\Python\Python310\site-packages\django\db\models\query.py", line 679, in create
    obj.save(force_insert=True, using=self.db)
  File "C:\Users\bayro\AppData\Roaming\Python\Python310\site-packages\django\db\models\base.py", line 822, in save
    self.save_base(
  File "C:\Users\bayro\AppData\Roaming\Python\Python310\site-packages\django\db\models\base.py", line 909, in save_base
    updated = self._save_table(
  File "C:\Users\bayro\AppData\Roaming\Python\Python310\site-packages\django\db\models\base.py", line 1071, in _save_table
    results = self._do_insert(
  File "C:\Users\bayro\AppData\Roaming\Python\Python310\site-packages\django\db\models\base.py", line 1112, in _do_insert
    return manager._insert(
  File "C:\Users\bayro\AppData\Roaming\Python\Python310\site-packages\django\db\models\manager.py", line 87, in manager_method
    return getattr(self.get_queryset(), name)(*args, **kwargs)
  File "C:\Users\bayro\AppData\Roaming\Python\Python310\site-packages\django\db\models\query.py", line 1847, in _insert
    return query.get_compiler(using=using).execute_sql(returning_fields)
  File "C:\Users\bayro\AppData\Roaming\Python\Python310\site-packages\django\db\models\sql\compiler.py", line 1823, in execute_sql
    cursor.execute(sql, params)
  File "C:\Users\bayro\AppData\Roaming\Python\Python310\site-packages\django\db\backends\utils.py", line 122, in execute
    return super().execute(sql, params)
  File "C:\Users\bayro\AppData\Roaming\Python\Python310\site-packages\django\db\backends\utils.py", line 79, in execute
    return self._execute_with_wrappers(
  File "C:\Users\bayro\AppData\Roaming\Python\Python310\site-packages\django\db\backends\utils.py", line 92, in _execute_with_wrappers
    return executor(sql, params, many, context)
  File "C:\Users\bayro\AppData\Roaming\Python\Python310\site-packages\django\db\backends\utils.py", line 100, in _execute
    with self.db.wrap_database_errors:
  File "C:\Users\bayro\AppData\Roaming\Python\Python310\site-packages\django\db\utils.py", line 91, in __exit__
    raise dj_exc_value.with_traceback(traceback) from exc_value
  File "C:\Users\bayro\AppData\Roaming\Python\Python310\site-packages\django\db\backends\utils.py", line 105, in _execute
    return self.cursor.execute(sql, params)
  File "C:\Users\bayro\AppData\Roaming\Python\Python310\site-packages\django\db\backends\sqlite3\base.py", line 329, in execute
    return super().execute(query, params)
django.db.utils.OperationalError: table roadmap_user has no column named chat_history
Internal Server Error: /chat/
Traceback (most recent call last):
  File "C:\Users\bayro\AppData\Roaming\Python\Python310\site-packages\django\db\backends\utils.py", line 105, in _execute
    return self.cursor.execute(sql, params)
  File "C:\Users\bayro\AppData\Roaming\Python\Python310\site-packages\django\db\backends\sqlite3\base.py", line 329, in execute
    return super().execute(query, params)
sqlite3.OperationalError: table roadmap_user has no column named chat_history

The above exception was the direct cause of the following exception:

Traceback (most recent call last):
  File "C:\Users\bayro\AppData\Roaming\Python\Python310\site-packages\django\core\handlers\exception.py", line 55, in inner
    response = get_response(request)
  File "C:\Users\bayro\AppData\Roaming\Python\Python310\site-packages\django\core\handlers\base.py", line 197, in _get_response
    response = wrapped_callback(request, *callback_args, **callback_kwargs)
  File "C:\Users\bayro\Desktop\IngSoftware\career_roadmap\roadmap\views.py", line 15, in chat
    user = User.objects.create()
  File "C:\Users\bayro\AppData\Roaming\Python\Python310\site-packages\django\db\models\manager.py", line 87, in manager_method
    return getattr(self.get_queryset(), name)(*args, **kwargs)
  File "C:\Users\bayro\AppData\Roaming\Python\Python310\site-packages\django\db\models\query.py", line 679, in create
    obj.save(force_insert=True, using=self.db)
  File "C:\Users\bayro\AppData\Roaming\Python\Python310\site-packages\django\db\models\base.py", line 822, in save
    self.save_base(
  File "C:\Users\bayro\AppData\Roaming\Python\Python310\site-packages\django\db\models\base.py", line 909, in save_base
    updated = self._save_table(
  File "C:\Users\bayro\AppData\Roaming\Python\Python310\site-packages\django\db\models\base.py", line 1071, in _save_table
    results = self._do_insert(
  File "C:\Users\bayro\AppData\Roaming\Python\Python310\site-packages\django\db\models\base.py", line 1112, in _do_insert
    return manager._insert(
  File "C:\Users\bayro\AppData\Roaming\Python\Python310\site-packages\django\db\models\manager.py", line 87, in manager_method
    return getattr(self.get_queryset(), name)(*args, **kwargs)
  File "C:\Users\bayro\AppData\Roaming\Python\Python310\site-packages\django\db\models\query.py", line 1847, in _insert
    return query.get_compiler(using=using).execute_sql(returning_fields)
  File "C:\Users\bayro\AppData\Roaming\Python\Python310\site-packages\django\db\models\sql\compiler.py", line 1823, in execute_sql
    cursor.execute(sql, params)
  File "C:\Users\bayro\AppData\Roaming\Python\Python310\site-packages\django\db\backends\utils.py", line 122, in execute
    return super().execute(sql, params)
  File "C:\Users\bayro\AppData\Roaming\Python\Python310\site-packages\django\db\backends\utils.py", line 79, in execute
    return self._execute_with_wrappers(
  File "C:\Users\bayro\AppData\Roaming\Python\Python310\site-packages\django\db\backends\utils.py", line 92, in _execute_with_wrappers
    return executor(sql, params, many, context)
  File "C:\Users\bayro\AppData\Roaming\Python\Python310\site-packages\django\db\backends\utils.py", line 100, in _execute
    with self.db.wrap_database_errors:
  File "C:\Users\bayro\AppData\Roaming\Python\Python310\site-packages\django\db\utils.py", line 91, in __exit__
    raise dj_exc_value.with_traceback(traceback) from exc_value
  File "C:\Users\bayro\AppData\Roaming\Python\Python310\site-packages\django\db\backends\utils.py", line 105, in _execute
    return self.cursor.execute(sql, params)
  File "C:\Users\bayro\AppData\Roaming\Python\Python310\site-packages\django\db\backends\sqlite3\base.py", line 329, in execute
    return super().execute(query, params)
django.db.utils.OperationalError: table roadmap_user has no column named chat_history
Internal Server Error: /chat/
Traceback (most recent call last):
  File "C:\Users\bayro\AppData\Roaming\Python\Python310\site-packages\django\db\backends\utils.py", line 105, in _execute
    return self.cursor.execute(sql, params)
  File "C:\Users\bayro\AppData\Roaming\Python\Python310\site-packages\django\db\backends\sqlite3\base.py", line 329, in execute
    return super().execute(query, params)
sqlite3.OperationalError: table roadmap_user has no column named chat_history

The above exception was the direct cause of the following exception:

Traceback (most recent call last):
  File "C:\Users\bayro\AppData\Roaming\Python\Python310\site-packages\django\core\handlers\exception.py", line 55, in inner
    response = get_response(request)
  File "C:\Users\bayro\AppData\Roaming\Python\Python310\site-packages\django\core\handlers\base.py", line 197, in _get_response
    response = wrapped_callback(request, *callback_args, **callback_kwargs)
  File "C:\Users\bayro\Desktop\IngSoftware\career_roadmap\roadmap\views.py", line 15, in chat
    user = User.objects.create()
  File "C:\Users\bayro\AppData\Roaming\Python\Python310\site-packages\django\db\models\manager.py", line 87, in manager_method
    return getattr(self.get_queryset(), name)(*args, **kwargs)
  File "C:\Users\bayro\AppData\Roaming\Python\Python310\site-packages\django\db\models\query.py", line 679, in create
    obj.save(force_insert=True, using=self.db)
  File "C:\Users\bayro\AppData\Roaming\Python\Python310\site-packages\django\db\models\base.py", line 822, in save
    self.save_base(
  File "C:\Users\bayro\AppData\Roaming\Python\Python310\site-packages\django\db\models\base.py", line 909, in save_base
    updated = self._save_table(
  File "C:\Users\bayro\AppData\Roaming\Python\Python310\site-packages\django\db\models\base.py", line 1071, in _save_table
    results = self._do_insert(
  File "C:\Users\bayro\AppData\Roaming\Python\Python310\site-packages\django\db\models\base.py", line 1112, in _do_insert
    return manager._insert(
  File "C:\Users\bayro\AppData\Roaming\Python\Python310\site-packages\django\db\models\manager.py", line 87, in manager_method
    return getattr(self.get_queryset(), name)(*args, **kwargs)
  File "C:\Users\bayro\AppData\Roaming\Python\Python310\site-packages\django\db\models\query.py", line 1847, in _insert
    return query.get_compiler(using=using).execute_sql(returning_fields)
  File "C:\Users\bayro\AppData\Roaming\Python\Python310\site-packages\django\db\models\sql\compiler.py", line 1823, in execute_sql
    cursor.execute(sql, params)
  File "C:\Users\bayro\AppData\Roaming\Python\Python310\site-packages\django\db\backends\utils.py", line 122, in execute
    return super().execute(sql, params)
  File "C:\Users\bayro\AppData\Roaming\Python\Python310\site-packages\django\db\backends\utils.py", line 79, in execute
    return self._execute_with_wrappers(
  File "C:\Users\bayro\AppData\Roaming\Python\Python310\site-packages\django\db\backends\utils.py", line 92, in _execute_with_wrappers
    return executor(sql, params, many, context)
  File "C:\Users\bayro\AppData\Roaming\Python\Python310\site-packages\django\db\backends\utils.py", line 100, in _execute
    with self.db.wrap_database_errors:
  File "C:\Users\bayro\AppData\Roaming\Python\Python310\site-packages\django\db\utils.py", line 91, in __exit__
    raise dj_exc_value.with_traceback(traceback) from exc_value
  File "C:\Users\bayro\AppData\Roaming\Python\Python310\site-packages\django\db\backends\utils.py", line 105, in _execute
    return self.cursor.execute(sql, params)
  File "C:\Users\bayro\AppData\Roaming\Python\Python310\site-packages\django\db\backends\sqlite3\base.py", line 329, in execute
    return super().execute(query, params)
django.db.utils.OperationalError: table roadmap_user has no column named chat_history
Internal Server Error: /chat/
Traceback (most recent call last):
  File "C:\Users\bayro\AppData\Roaming\Python\Python310\site-packages\django\db\backends\utils.py", line 105, in _execute
    return self.cursor.execute(sql, params)
  File "C:\Users\bayro\AppData\Roaming\Python\Python310\site-packages\django\db\backends\sqlite3\base.py", line 329, in execute
    return super().execute(query, params)
sqlite3.OperationalError: table roadmap_user has no column named chat_history

The above exception was the direct cause of the following exception:

Traceback (most recent call last):
  File "C:\Users\bayro\AppData\Roaming\Python\Python310\site-packages\django\core\handlers\exception.py", line 55, in inner
    response = get_response(request)
  File "C:\Users\bayro\AppData\Roaming\Python\Python310\site-packages\django\core\handlers\base.py", line 197, in _get_response
    response = wrapped_callback(request, *callback_args, **callback_kwargs)
  File "C:\Users\bayro\Desktop\IngSoftware\career_roadmap\roadmap\views.py", line 15, in chat
    user = User.objects.create()
  File "C:\Users\bayro\AppData\Roaming\Python\Python310\site-packages\django\db\models\manager.py", line 87, in manager_method
    return getattr(self.get_queryset(), name)(*args, **kwargs)
  File "C:\Users\bayro\AppData\Roaming\Python\Python310\site-packages\django\db\models\query.py", line 679, in create
    obj.save(force_insert=True, using=self.db)
  File "C:\Users\bayro\AppData\Roaming\Python\Python310\site-packages\django\db\models\base.py", line 822, in save
    self.save_base(
  File "C:\Users\bayro\AppData\Roaming\Python\Python310\site-packages\django\db\models\base.py", line 909, in save_base
    updated = self._save_table(
  File "C:\Users\bayro\AppData\Roaming\Python\Python310\site-packages\django\db\models\base.py", line 1071, in _save_table
    results = self._do_insert(
  File "C:\Users\bayro\AppData\Roaming\Python\Python310\site-packages\django\db\models\base.py", line 1112, in _do_insert
    return manager._insert(
  File "C:\Users\bayro\AppData\Roaming\Python\Python310\site-packages\django\db\models\manager.py", line 87, in manager_method
    return getattr(self.get_queryset(), name)(*args, **kwargs)
  File "C:\Users\bayro\AppData\Roaming\Python\Python310\site-packages\django\db\models\query.py", line 1847, in _insert
    return query.get_compiler(using=using).execute_sql(returning_fields)
  File "C:\Users\bayro\AppData\Roaming\Python\Python310\site-packages\django\db\models\sql\compiler.py", line 1823, in execute_sql
    cursor.execute(sql, params)
  File "C:\Users\bayro\AppData\Roaming\Python\Python310\site-packages\django\db\backends\utils.py", line 122, in execute
    return super().execute(sql, params)
  File "C:\Users\bayro\AppData\Roaming\Python\Python310\site-packages\django\db\backends\utils.py", line 79, in execute
    return self._execute_with_wrappers(
  File "C:\Users\bayro\AppData\Roaming\Python\Python310\site-packages\django\db\backends\utils.py", line 92, in _execute_with_wrappers
    return executor(sql, params, many, context)
  File "C:\Users\bayro\AppData\Roaming\Python\Python310\site-packages\django\db\backends\utils.py", line 100, in _execute
    with self.db.wrap_database_errors:
  File "C:\Users\bayro\AppData\Roaming\Python\Python310\site-packages\django\db\utils.py", line 91, in __exit__
    raise dj_exc_value.with_traceback(traceback) from exc_value
  File "C:\Users\bayro\AppData\Roaming\Python\Python310\site-packages\django\db\backends\utils.py", line 105, in _execute
    return self.cursor.execute(sql, params)
  File "C:\Users\bayro\AppData\Roaming\Python\Python310\site-packages\django\db\backends\sqlite3\base.py", line 329, in execute
    return super().execute(query, params)
django.db.utils.OperationalError: table roadmap_user has no column named chat_history
Internal Server Error: /chat/
Traceback (most recent call last):
  File "C:\Users\bayro\AppData\Roaming\Python\Python310\site-packages\django\db\backends\utils.py", line 105, in _execute
    return self.cursor.execute(sql, params)
  File "C:\Users\bayro\AppData\Roaming\Python\Python310\site-packages\django\db\backends\sqlite3\base.py", line 329, in execute
    return super().execute(query, params)
sqlite3.OperationalError: table roadmap_user has no column named chat_history

The above exception was the direct cause of the following exception:

Traceback (most recent call last):
  File "C:\Users\bayro\AppData\Roaming\Python\Python310\site-packages\django\core\handlers\exception.py", line 55, in inner
    response = get_response(request)
  File "C:\Users\bayro\AppData\Roaming\Python\Python310\site-packages\django\core\handlers\base.py", line 197, in _get_response
    response = wrapped_callback(request, *callback_args, **callback_kwargs)
  File "C:\Users\bayro\Desktop\IngSoftware\career_roadmap\roadmap\views.py", line 15, in chat
    user = User.objects.create()
  File "C:\Users\bayro\AppData\Roaming\Python\Python310\site-packages\django\db\models\manager.py", line 87, in manager_method
    return getattr(self.get_queryset(), name)(*args, **kwargs)
  File "C:\Users\bayro\AppData\Roaming\Python\Python310\site-packages\django\db\models\query.py", line 679, in create
    obj.save(force_insert=True, using=self.db)
  File "C:\Users\bayro\AppData\Roaming\Python\Python310\site-packages\django\db\models\base.py", line 822, in save
    self.save_base(
  File "C:\Users\bayro\AppData\Roaming\Python\Python310\site-packages\django\db\models\base.py", line 909, in save_base
    updated = self._save_table(
  File "C:\Users\bayro\AppData\Roaming\Python\Python310\site-packages\django\db\models\base.py", line 1071, in _save_table
    results = self._do_insert(
  File "C:\Users\bayro\AppData\Roaming\Python\Python310\site-packages\django\db\models\base.py", line 1112, in _do_insert
    return manager._insert(
  File "C:\Users\bayro\AppData\Roaming\Python\Python310\site-packages\django\db\models\manager.py", line 87, in manager_method
    return getattr(self.get_queryset(), name)(*args, **kwargs)
  File "C:\Users\bayro\AppData\Roaming\Python\Python310\site-packages\django\db\models\query.py", line 1847, in _insert
    return query.get_compiler(using=using).execute_sql(returning_fields)
  File "C:\Users\bayro\AppData\Roaming\Python\Python310\site-packages\django\db\models\sql\compiler.py", line 1823, in execute_sql
    cursor.execute(sql, params)
  File "C:\Users\bayro\AppData\Roaming\Python\Python310\site-packages\django\db\backends\utils.py", line 122, in execute
    return super().execute(sql, params)
  File "C:\Users\bayro\AppData\Roaming\Python\Python310\site-packages\django\db\backends\utils.py", line 79, in execute
    return self._execute_with_wrappers(
  File "C:\Users\bayro\AppData\Roaming\Python\Python310\site-packages\django\db\backends\utils.py", line 92, in _execute_with_wrappers
    return executor(sql, params, many, context)
  File "C:\Users\bayro\AppData\Roaming\Python\Python310\site-packages\django\db\backends\utils.py", line 100, in _execute
    with self.db.wrap_database_errors:
  File "C:\Users\bayro\AppData\Roaming\Python\Python310\site-packages\django\db\utils.py", line 91, in __exit__
    raise dj_exc_value.with_traceback(traceback) from exc_value
  File "C:\Users\bayro\AppData\Roaming\Python\Python310\site-packages\django\db\backends\utils.py", line 105, in _execute
    return self.cursor.execute(sql, params)
  File "C:\Users\bayro\AppData\Roaming\Python\Python310\site-packages\django\db\backends\sqlite3\base.py", line 329, in execute
    return super().execute(query, params)
django.db.utils.OperationalError: table roadmap_user has no column named chat_history
Internal Server Error: /chat/
Traceback (most recent call last):
  File "C:\Users\bayro\AppData\Roaming\Python\Python310\site-packages\django\db\backends\utils.py", line 105, in _execute
    return self.cursor.execute(sql, params)
  File "C:\Users\bayro\AppData\Roaming\Python\Python310\site-packages\django\db\backends\sqlite3\base.py", line 329, in execute
    return super().execute(query, params)
sqlite3.OperationalError: table roadmap_user has no column named chat_history

The above exception was the direct cause of the following exception:

Traceback (most recent call last):
  File "C:\Users\bayro\AppData\Roaming\Python\Python310\site-packages\django\core\handlers\exception.py", line 55, in inner
    response = get_response(request)
  File "C:\Users\bayro\AppData\Roaming\Python\Python310\site-packages\django\core\handlers\base.py", line 197, in _get_response
    response = wrapped_callback(request, *callback_args, **callback_kwargs)
  File "C:\Users\bayro\Desktop\IngSoftware\career_roadmap\roadmap\views.py", line 15, in chat
    user = User.objects.create()
  File "C:\Users\bayro\AppData\Roaming\Python\Python310\site-packages\django\db\models\manager.py", line 87, in manager_method
    return getattr(self.get_queryset(), name)(*args, **kwargs)
  File "C:\Users\bayro\AppData\Roaming\Python\Python310\site-packages\django\db\models\query.py", line 679, in create
    obj.save(force_insert=True, using=self.db)
  File "C:\Users\bayro\AppData\Roaming\Python\Python310\site-packages\django\db\models\base.py", line 822, in save
    self.save_base(
  File "C:\Users\bayro\AppData\Roaming\Python\Python310\site-packages\django\db\models\base.py", line 909, in save_base
    updated = self._save_table(
  File "C:\Users\bayro\AppData\Roaming\Python\Python310\site-packages\django\db\models\base.py", line 1071, in _save_table
    results = self._do_insert(
  File "C:\Users\bayro\AppData\Roaming\Python\Python310\site-packages\django\db\models\base.py", line 1112, in _do_insert
    return manager._insert(
  File "C:\Users\bayro\AppData\Roaming\Python\Python310\site-packages\django\db\models\manager.py", line 87, in manager_method
    return getattr(self.get_queryset(), name)(*args, **kwargs)
  File "C:\Users\bayro\AppData\Roaming\Python\Python310\site-packages\django\db\models\query.py", line 1847, in _insert
    return query.get_compiler(using=using).execute_sql(returning_fields)
  File "C:\Users\bayro\AppData\Roaming\Python\Python310\site-packages\django\db\models\sql\compiler.py", line 1823, in execute_sql
    cursor.execute(sql, params)
  File "C:\Users\bayro\AppData\Roaming\Python\Python310\site-packages\django\db\backends\utils.py", line 122, in execute
    return super().execute(sql, params)
  File "C:\Users\bayro\AppData\Roaming\Python\Python310\site-packages\django\db\backends\utils.py", line 79, in execute
    return self._execute_with_wrappers(
  File "C:\Users\bayro\AppData\Roaming\Python\Python310\site-packages\django\db\backends\utils.py", line 92, in _execute_with_wrappers
    return executor(sql, params, many, context)
  File "C:\Users\bayro\AppData\Roaming\Python\Python310\site-packages\django\db\backends\utils.py", line 100, in _execute
    with self.db.wrap_database_errors:
  File "C:\Users\bayro\AppData\Roaming\Python\Python310\site-packages\django\db\utils.py", line 91, in __exit__
    raise dj_exc_value.with_traceback(traceback) from exc_value
  File "C:\Users\bayro\AppData\Roaming\Python\Python310\site-packages\django\db\backends\utils.py", line 105, in _execute
    return self.cursor.execute(sql, params)
  File "C:\Users\bayro\AppData\Roaming\Python\Python310\site-packages\django\db\backends\sqlite3\base.py", line 329, in execute
    return super().execute(query, params)
django.db.utils.OperationalError: table roadmap_user has no column named chat_history
Internal Server Error: /chat/
Traceback (most recent call last):
  File "C:\Users\bayro\AppData\Roaming\Python\Python310\site-packages\django\db\backends\utils.py", line 105, in _execute
    return self.cursor.execute(sql, params)
  File "C:\Users\bayro\AppData\Roaming\Python\Python310\site-packages\django\db\backends\sqlite3\base.py", line 329, in execute
    return super().execute(query, params)
sqlite3.OperationalError: table roadmap_user has no column named chat_history

The above exception was the direct cause of the following exception:

Traceback (most recent call last):
  File "C:\Users\bayro\AppData\Roaming\Python\Python310\site-packages\django\core\handlers\exception.py", line 55, in inner
    response = get_response(request)
  File "C:\Users\bayro\AppData\Roaming\Python\Python310\site-packages\django\core\handlers\base.py", line 197, in _get_response
    response = wrapped_callback(request, *callback_args, **callback_kwargs)
  File "C:\Users\bayro\Desktop\IngSoftware\career_roadmap\roadmap\views.py", line 15, in chat
    user = User.objects.create()
  File "C:\Users\bayro\AppData\Roaming\Python\Python310\site-packages\django\db\models\manager.py", line 87, in manager_method
    return getattr(self.get_queryset(), name)(*args, **kwargs)
  File "C:\Users\bayro\AppData\Roaming\Python\Python310\site-packages\django\db\models\query.py", line 679, in create
    obj.save(force_insert=True, using=self.db)
  File "C:\Users\bayro\AppData\Roaming\Python\Python310\site-packages\django\db\models\base.py", line 822, in save
    self.save_base(
  File "C:\Users\bayro\AppData\Roaming\Python\Python310\site-packages\django\db\models\base.py", line 909, in save_base
    updated = self._save_table(
  File "C:\Users\bayro\AppData\Roaming\Python\Python310\site-packages\django\db\models\base.py", line 1071, in _save_table
    results = self._do_insert(
  File "C:\Users\bayro\AppData\Roaming\Python\Python310\site-packages\django\db\models\base.py", line 1112, in _do_insert
    return manager._insert(
  File "C:\Users\bayro\AppData\Roaming\Python\Python310\site-packages\django\db\models\manager.py", line 87, in manager_method
    return getattr(self.get_queryset(), name)(*args, **kwargs)
  File "C:\Users\bayro\AppData\Roaming\Python\Python310\site-packages\django\db\models\query.py", line 1847, in _insert
    return query.get_compiler(using=using).execute_sql(returning_fields)
  File "C:\Users\bayro\AppData\Roaming\Python\Python310\site-packages\django\db\models\sql\compiler.py", line 1823, in execute_sql
    cursor.execute(sql, params)
  File "C:\Users\bayro\AppData\Roaming\Python\Python310\site-packages\django\db\backends\utils.py", line 122, in execute
    return super().execute(sql, params)
  File "C:\Users\bayro\AppData\Roaming\Python\Python310\site-packages\django\db\backends\utils.py", line 79, in execute
    return self._execute_with_wrappers(
  File "C:\Users\bayro\AppData\Roaming\Python\Python310\site-packages\django\db\backends\utils.py", line 92, in _execute_with_wrappers
    return executor(sql, params, many, context)
  File "C:\Users\bayro\AppData\Roaming\Python\Python310\site-packages\django\db\backends\utils.py", line 100, in _execute
    with self.db.wrap_database_errors:
  File "C:\Users\bayro\AppData\Roaming\Python\Python310\site-packages\django\db\utils.py", line 91, in __exit__
    raise dj_exc_value.with_traceback(traceback) from exc_value
  File "C:\Users\bayro\AppData\Roaming\Python\Python310\site-packages\django\db\backends\utils.py", line 105, in _execute
    return self.cursor.execute(sql, params)
  File "C:\Users\bayro\AppData\Roaming\Python\Python310\site-packages\django\db\backends\sqlite3\base.py", line 329, in execute
    return super().execute(query, params)
django.db.utils.OperationalError: table roadmap_user has no column named chat_history
Internal Server Error: /chat/
Traceback (most recent call last):
  File "C:\Users\bayro\AppData\Roaming\Python\Python310\site-packages\django\db\backends\utils.py", line 105, in _execute
    return self.cursor.execute(sql, params)
  File "C:\Users\bayro\AppData\Roaming\Python\Python310\site-packages\django\db\backends\sqlite3\base.py", line 329, in execute
    return super().execute(query, params)
sqlite3.OperationalError: table roadmap_user has no column named chat_history

The above exception was the direct cause of the following exception:

Traceback (most recent call last):
  File "C:\Users\bayro\AppData\Roaming\Python\Python310\site-packages\django\core\handlers\exception.py", line 55, in inner
    response = get_response(request)
  File "C:\Users\bayro\AppData\Roaming\Python\Python310\site-packages\django\core\handlers\base.py", line 197, in _get_response
    response = wrapped_callback(request, *callback_args, **callback_kwargs)
  File "C:\Users\bayro\Desktop\IngSoftware\career_roadmap\roadmap\views.py", line 15, in chat
    user = User.objects.create()
  File "C:\Users\bayro\AppData\Roaming\Python\Python310\site-packages\django\db\models\manager.py", line 87, in manager_method
    return getattr(self.get_queryset(), name)(*args, **kwargs)
  File "C:\Users\bayro\AppData\Roaming\Python\Python310\site-packages\django\db\models\query.py", line 679, in create
    obj.save(force_insert=True, using=self.db)
  File "C:\Users\bayro\AppData\Roaming\Python\Python310\site-packages\django\db\models\base.py", line 822, in save
    self.save_base(
  File "C:\Users\bayro\AppData\Roaming\Python\Python310\site-packages\django\db\models\base.py", line 909, in save_base
    updated = self._save_table(
  File "C:\Users\bayro\AppData\Roaming\Python\Python310\site-packages\django\db\models\base.py", line 1071, in _save_table
    results = self._do_insert(
  File "C:\Users\bayro\AppData\Roaming\Python\Python310\site-packages\django\db\models\base.py", line 1112, in _do_insert
    return manager._insert(
  File "C:\Users\bayro\AppData\Roaming\Python\Python310\site-packages\django\db\models\manager.py", line 87, in manager_method
    return getattr(self.get_queryset(), name)(*args, **kwargs)
  File "C:\Users\bayro\AppData\Roaming\Python\Python310\site-packages\django\db\models\query.py", line 1847, in _insert
    return query.get_compiler(using=using).execute_sql(returning_fields)
  File "C:\Users\bayro\AppData\Roaming\Python\Python310\site-packages\django\db\models\sql\compiler.py", line 1823, in execute_sql
    cursor.execute(sql, params)
  File "C:\Users\bayro\AppData\Roaming\Python\Python310\site-packages\django\db\backends\utils.py", line 122, in execute
    return super().execute(sql, params)
  File "C:\Users\bayro\AppData\Roaming\Python\Python310\site-packages\django\db\backends\utils.py", line 79, in execute
    return self._execute_with_wrappers(
  File "C:\Users\bayro\AppData\Roaming\Python\Python310\site-packages\django\db\backends\utils.py", line 92, in _execute_with_wrappers
    return executor(sql, params, many, context)
  File "C:\Users\bayro\AppData\Roaming\Python\Python310\site-packages\django\db\backends\utils.py", line 100, in _execute
    with self.db.wrap_database_errors:
  File "C:\Users\bayro\AppData\Roaming\Python\Python310\site-packages\django\db\utils.py", line 91, in __exit__
    raise dj_exc_value.with_traceback(traceback) from exc_value
  File "C:\Users\bayro\AppData\Roaming\Python\Python310\site-packages\django\db\backends\utils.py", line 105, in _execute
    return self.cursor.execute(sql, params)
  File "C:\Users\bayro\AppData\Roaming\Python\Python310\site-packages\django\db\backends\sqlite3\base.py", line 329, in execute
    return super().execute(query, params)
django.db.utils.OperationalError: table roadmap_user has no column named chat_history
Internal Server Error: /chat/
Traceback (most recent call last):
  File "C:\Users\bayro\AppData\Roaming\Python\Python310\site-packages\django\db\backends\utils.py", line 105, in _execute
    return self.cursor.execute(sql, params)
  File "C:\Users\bayro\AppData\Roaming\Python\Python310\site-packages\django\db\backends\sqlite3\base.py", line 329, in execute
    return super().execute(query, params)
sqlite3.OperationalError: table roadmap_user has no column named chat_history

The above exception was the direct cause of the following exception:

Traceback (most recent call last):
  File "C:\Users\bayro\AppData\Roaming\Python\Python310\site-packages\django\core\handlers\exception.py", line 55, in inner
    response = get_response(request)
  File "C:\Users\bayro\AppData\Roaming\Python\Python310\site-packages\django\core\handlers\base.py", line 197, in _get_response
    response = wrapped_callback(request, *callback_args, **callback_kwargs)
  File "C:\Users\bayro\Desktop\IngSoftware\career_roadmap\roadmap\views.py", line 15, in chat
    user = User.objects.create()
  File "C:\Users\bayro\AppData\Roaming\Python\Python310\site-packages\django\db\models\manager.py", line 87, in manager_method
    return getattr(self.get_queryset(), name)(*args, **kwargs)
  File "C:\Users\bayro\AppData\Roaming\Python\Python310\site-packages\django\db\models\query.py", line 679, in create
    obj.save(force_insert=True, using=self.db)
  File "C:\Users\bayro\AppData\Roaming\Python\Python310\site-packages\django\db\models\base.py", line 822, in save
    self.save_base(
  File "C:\Users\bayro\AppData\Roaming\Python\Python310\site-packages\django\db\models\base.py", line 909, in save_base
    updated = self._save_table(
  File "C:\Users\bayro\AppData\Roaming\Python\Python310\site-packages\django\db\models\base.py", line 1071, in _save_table
    results = self._do_insert(
  File "C:\Users\bayro\AppData\Roaming\Python\Python310\site-packages\django\db\models\base.py", line 1112, in _do_insert
    return manager._insert(
  File "C:\Users\bayro\AppData\Roaming\Python\Python310\site-packages\django\db\models\manager.py", line 87, in manager_method
    return getattr(self.get_queryset(), name)(*args, **kwargs)
  File "C:\Users\bayro\AppData\Roaming\Python\Python310\site-packages\django\db\models\query.py", line 1847, in _insert
    return query.get_compiler(using=using).execute_sql(returning_fields)
  File "C:\Users\bayro\AppData\Roaming\Python\Python310\site-packages\django\db\models\sql\compiler.py", line 1823, in execute_sql
    cursor.execute(sql, params)
  File "C:\Users\bayro\AppData\Roaming\Python\Python310\site-packages\django\db\backends\utils.py", line 122, in execute
    return super().execute(sql, params)
  File "C:\Users\bayro\AppData\Roaming\Python\Python310\site-packages\django\db\backends\utils.py", line 79, in execute
    return self._execute_with_wrappers(
  File "C:\Users\bayro\AppData\Roaming\Python\Python310\site-packages\django\db\backends\utils.py", line 92, in _execute_with_wrappers
    return executor(sql, params, many, context)
  File "C:\Users\bayro\AppData\Roaming\Python\Python310\site-packages\django\db\backends\utils.py", line 100, in _execute
    with self.db.wrap_database_errors:
  File "C:\Users\bayro\AppData\Roaming\Python\Python310\site-packages\django\db\utils.py", line 91, in __exit__
    raise dj_exc_value.with_traceback(traceback) from exc_value
  File "C:\Users\bayro\AppData\Roaming\Python\Python310\site-packages\django\db\backends\utils.py", line 105, in _execute
    return self.cursor.execute(sql, params)
  File "C:\Users\bayro\AppData\Roaming\Python\Python310\site-packages\django\db\backends\sqlite3\base.py", line 329, in execute
    return super().execute(query, params)
django.db.utils.OperationalError: table roadmap_user has no column named chat_history
Internal Server Error: /chat/
Traceback (most recent call last):
  File "C:\Users\bayro\AppData\Roaming\Python\Python310\site-packages\django\db\backends\utils.py", line 105, in _execute
    return self.cursor.execute(sql, params)
  File "C:\Users\bayro\AppData\Roaming\Python\Python310\site-packages\django\db\backends\sqlite3\base.py", line 329, in execute
    return super().execute(query, params)
sqlite3.OperationalError: table roadmap_user has no column named chat_history

The above exception was the direct cause of the following exception:

Traceback (most recent call last):
  File "C:\Users\bayro\AppData\Roaming\Python\Python310\site-packages\django\core\handlers\exception.py", line 55, in inner
    response = get_response(request)
  File "C:\Users\bayro\AppData\Roaming\Python\Python310\site-packages\django\core\handlers\base.py", line 197, in _get_response
    response = wrapped_callback(request, *callback_args, **callback_kwargs)
  File "C:\Users\bayro\Desktop\IngSoftware\career_roadmap\roadmap\views.py", line 15, in chat
    user = User.objects.create()
  File "C:\Users\bayro\AppData\Roaming\Python\Python310\site-packages\django\db\models\manager.py", line 87, in manager_method
    return getattr(self.get_queryset(), name)(*args, **kwargs)
  File "C:\Users\bayro\AppData\Roaming\Python\Python310\site-packages\django\db\models\query.py", line 679, in create
    obj.save(force_insert=True, using=self.db)
  File "C:\Users\bayro\AppData\Roaming\Python\Python310\site-packages\django\db\models\base.py", line 822, in save
    self.save_base(
  File "C:\Users\bayro\AppData\Roaming\Python\Python310\site-packages\django\db\models\base.py", line 909, in save_base
    updated = self._save_table(
  File "C:\Users\bayro\AppData\Roaming\Python\Python310\site-packages\django\db\models\base.py", line 1071, in _save_table
    results = self._do_insert(
  File "C:\Users\bayro\AppData\Roaming\Python\Python310\site-packages\django\db\models\base.py", line 1112, in _do_insert
    return manager._insert(
  File "C:\Users\bayro\AppData\Roaming\Python\Python310\site-packages\django\db\models\manager.py", line 87, in manager_method
    return getattr(self.get_queryset(), name)(*args, **kwargs)
  File "C:\Users\bayro\AppData\Roaming\Python\Python310\site-packages\django\db\models\query.py", line 1847, in _insert
    return query.get_compiler(using=using).execute_sql(returning_fields)
  File "C:\Users\bayro\AppData\Roaming\Python\Python310\site-packages\django\db\models\sql\compiler.py", line 1823, in execute_sql
    cursor.execute(sql, params)
  File "C:\Users\bayro\AppData\Roaming\Python\Python310\site-packages\django\db\backends\utils.py", line 122, in execute
    return super().execute(sql, params)
  File "C:\Users\bayro\AppData\Roaming\Python\Python310\site-packages\django\db\backends\utils.py", line 79, in execute
    return self._execute_with_wrappers(
  File "C:\Users\bayro\AppData\Roaming\Python\Python310\site-packages\django\db\backends\utils.py", line 92, in _execute_with_wrappers
    return executor(sql, params, many, context)
  File "C:\Users\bayro\AppData\Roaming\Python\Python310\site-packages\django\db\backends\utils.py", line 100, in _execute
    with self.db.wrap_database_errors:
  File "C:\Users\bayro\AppData\Roaming\Python\Python310\site-packages\django\db\utils.py", line 91, in __exit__
    raise dj_exc_value.with_traceback(traceback) from exc_value
  File "C:\Users\bayro\AppData\Roaming\Python\Python310\site-packages\django\db\backends\utils.py", line 105, in _execute
    return self.cursor.execute(sql, params)
  File "C:\Users\bayro\AppData\Roaming\Python\Python310\site-packages\django\db\backends\sqlite3\base.py", line 329, in execute
    return super().execute(query, params)
django.db.utils.OperationalError: table roadmap_user has no column named chat_history
Internal Server Error: /chat/
Traceback (most recent call last):
  File "C:\Users\bayro\AppData\Roaming\Python\Python310\site-packages\django\db\backends\utils.py", line 105, in _execute
    return self.cursor.execute(sql, params)
  File "C:\Users\bayro\AppData\Roaming\Python\Python310\site-packages\django\db\backends\sqlite3\base.py", line 329, in execute
    return super().execute(query, params)
sqlite3.OperationalError: table roadmap_user has no column named chat_history

The above exception was the direct cause of the following exception:

Traceback (most recent call last):
  File "C:\Users\bayro\AppData\Roaming\Python\Python310\site-packages\django\core\handlers\exception.py", line 55, in inner
    response = get_response(request)
  File "C:\Users\bayro\AppData\Roaming\Python\Python310\site-packages\django\core\handlers\base.py", line 197, in _get_response
    response = wrapped_callback(request, *callback_args, **callback_kwargs)
  File "C:\Users\bayro\Desktop\IngSoftware\career_roadmap\roadmap\views.py", line 15, in chat
    user = User.objects.create()
  File "C:\Users\bayro\AppData\Roaming\Python\Python310\site-packages\django\db\models\manager.py", line 87, in manager_method
    return getattr(self.get_queryset(), name)(*args, **kwargs)
  File "C:\Users\bayro\AppData\Roaming\Python\Python310\site-packages\django\db\models\query.py", line 679, in create
    obj.save(force_insert=True, using=self.db)
  File "C:\Users\bayro\AppData\Roaming\Python\Python310\site-packages\django\db\models\base.py", line 822, in save
    self.save_base(
  File "C:\Users\bayro\AppData\Roaming\Python\Python310\site-packages\django\db\models\base.py", line 909, in save_base
    updated = self._save_table(
  File "C:\Users\bayro\AppData\Roaming\Python\Python310\site-packages\django\db\models\base.py", line 1071, in _save_table
    results = self._do_insert(
  File "C:\Users\bayro\AppData\Roaming\Python\Python310\site-packages\django\db\models\base.py", line 1112, in _do_insert
    return manager._insert(
  File "C:\Users\bayro\AppData\Roaming\Python\Python310\site-packages\django\db\models\manager.py", line 87, in manager_method
    return getattr(self.get_queryset(), name)(*args, **kwargs)
  File "C:\Users\bayro\AppData\Roaming\Python\Python310\site-packages\django\db\models\query.py", line 1847, in _insert
    return query.get_compiler(using=using).execute_sql(returning_fields)
  File "C:\Users\bayro\AppData\Roaming\Python\Python310\site-packages\django\db\models\sql\compiler.py", line 1823, in execute_sql
    cursor.execute(sql, params)
  File "C:\Users\bayro\AppData\Roaming\Python\Python310\site-packages\django\db\backends\utils.py", line 122, in execute
    return super().execute(sql, params)
  File "C:\Users\bayro\AppData\Roaming\Python\Python310\site-packages\django\db\backends\utils.py", line 79, in execute
    return self._execute_with_wrappers(
  File "C:\Users\bayro\AppData\Roaming\Python\Python310\site-packages\django\db\backends\utils.py", line 92, in _execute_with_wrappers
    return executor(sql, params, many, context)
  File "C:\Users\bayro\AppData\Roaming\Python\Python310\site-packages\django\db\backends\utils.py", line 100, in _execute
    with self.db.wrap_database_errors:
  File "C:\Users\bayro\AppData\Roaming\Python\Python310\site-packages\django\db\utils.py", line 91, in __exit__
    raise dj_exc_value.with_traceback(traceback) from exc_value
  File "C:\Users\bayro\AppData\Roaming\Python\Python310\site-packages\django\db\backends\utils.py", line 105, in _execute
    return self.cursor.execute(sql, params)
  File "C:\Users\bayro\AppData\Roaming\Python\Python310\site-packages\django\db\backends\sqlite3\base.py", line 329, in execute
    return super().execute(query, params)
django.db.utils.OperationalError: table roadmap_user has no column named chat_history
Internal Server Error: /chat/
Traceback (most recent call last):
  File "C:\Users\bayro\AppData\Roaming\Python\Python310\site-packages\django\db\backends\utils.py", line 105, in _execute
    return self.cursor.execute(sql, params)
  File "C:\Users\bayro\AppData\Roaming\Python\Python310\site-packages\django\db\backends\sqlite3\base.py", line 329, in execute
    return super().execute(query, params)
sqlite3.OperationalError: table roadmap_user has no column named chat_history

The above exception was the direct cause of the following exception:

Traceback (most recent call last):
  File "C:\Users\bayro\AppData\Roaming\Python\Python310\site-packages\django\core\handlers\exception.py", line 55, in inner
    response = get_response(request)
  File "C:\Users\bayro\AppData\Roaming\Python\Python310\site-packages\django\core\handlers\base.py", line 197, in _get_response
    response = wrapped_callback(request, *callback_args, **callback_kwargs)
  File "C:\Users\bayro\Desktop\IngSoftware\career_roadmap\roadmap\views.py", line 15, in chat
    user = User.objects.create()
  File "C:\Users\bayro\AppData\Roaming\Python\Python310\site-packages\django\db\models\manager.py", line 87, in manager_method
    return getattr(self.get_queryset(), name)(*args, **kwargs)
  File "C:\Users\bayro\AppData\Roaming\Python\Python310\site-packages\django\db\models\query.py", line 679, in create
    obj.save(force_insert=True, using=self.db)
  File "C:\Users\bayro\AppData\Roaming\Python\Python310\site-packages\django\db\models\base.py", line 822, in save
    self.save_base(
  File "C:\Users\bayro\AppData\Roaming\Python\Python310\site-packages\django\db\models\base.py", line 909, in save_base
    updated = self._save_table(
  File "C:\Users\bayro\AppData\Roaming\Python\Python310\site-packages\django\db\models\base.py", line 1071, in _save_table
    results = self._do_insert(
  File "C:\Users\bayro\AppData\Roaming\Python\Python310\site-packages\django\db\models\base.py", line 1112, in _do_insert
    return manager._insert(
  File "C:\Users\bayro\AppData\Roaming\Python\Python310\site-packages\django\db\models\manager.py", line 87, in manager_method
    return getattr(self.get_queryset(), name)(*args, **kwargs)
  File "C:\Users\bayro\AppData\Roaming\Python\Python310\site-packages\django\db\models\query.py", line 1847, in _insert
    return query.get_compiler(using=using).execute_sql(returning_fields)
  File "C:\Users\bayro\AppData\Roaming\Python\Python310\site-packages\django\db\models\sql\compiler.py", line 1823, in execute_sql
    cursor.execute(sql, params)
  File "C:\Users\bayro\AppData\Roaming\Python\Python310\site-packages\django\db\backends\utils.py", line 122, in execute
    return super().execute(sql, params)
  File "C:\Users\bayro\AppData\Roaming\Python\Python310\site-packages\django\db\backends\utils.py", line 79, in execute
    return self._execute_with_wrappers(
  File "C:\Users\bayro\AppData\Roaming\Python\Python310\site-packages\django\db\backends\utils.py", line 92, in _execute_with_wrappers
    return executor(sql, params, many, context)
  File "C:\Users\bayro\AppData\Roaming\Python\Python310\site-packages\django\db\backends\utils.py", line 100, in _execute
    with self.db.wrap_database_errors:
  File "C:\Users\bayro\AppData\Roaming\Python\Python310\site-packages\django\db\utils.py", line 91, in __exit__
    raise dj_exc_value.with_traceback(traceback) from exc_value
  File "C:\Users\bayro\AppData\Roaming\Python\Python310\site-packages\django\db\backends\utils.py", line 105, in _execute
    return self.cursor.execute(sql, params)
  File "C:\Users\bayro\AppData\Roaming\Python\Python310\site-packages\django\db\backends\sqlite3\base.py", line 329, in execute
    return super().execute(query, params)
django.db.utils.OperationalError: table roadmap_user has no column named chat_history
Internal Server Error: /signup/
Traceback (most recent call last):
  File "C:\Users\bayro\AppData\Roaming\Python\Python310\site-packages\django\core\handlers\exception.py", line 55, in inner
    response = get_response(request)
  File "C:\Users\bayro\AppData\Roaming\Python\Python310\site-packages\django\core\handlers\base.py", line 197, in _get_response
    response = wrapped_callback(request, *callback_args, **callback_kwargs)
  File "C:\Users\bayro\Desktop\IngSoftware\career_roadmap\roadmap\views.py", line 38, in signup
    if form.is_valid():
  File "C:\Users\bayro\AppData\Roaming\Python\Python310\site-packages\django\forms\forms.py", line 197, in is_valid
    return self.is_bound and not self.errors
  File "C:\Users\bayro\AppData\Roaming\Python\Python310\site-packages\django\forms\forms.py", line 192, in errors
    self.full_clean()
  File "C:\Users\bayro\AppData\Roaming\Python\Python310\site-packages\django\forms\forms.py", line 327, in full_clean
    self._clean_fields()
  File "C:\Users\bayro\AppData\Roaming\Python\Python310\site-packages\django\forms\forms.py", line 342, in _clean_fields
    value = getattr(self, "clean_%s" % name)()
  File "C:\Users\bayro\AppData\Roaming\Python\Python310\site-packages\django\contrib\auth\forms.py", line 163, in clean_username
    and self._meta.model.objects.filter(username__iexact=username).exists()
  File "C:\Users\bayro\AppData\Roaming\Python\Python310\site-packages\django\db\models\manager.py", line 196, in __get__
    raise AttributeError(
AttributeError: Manager isn't available; 'auth.User' has been swapped for 'roadmap.User'
Internal Server Error: /chat/
Traceback (most recent call last):
  File "C:\Users\bayro\AppData\Roaming\Python\Python310\site-packages\django\core\handlers\exception.py", line 55, in inner
    response = get_response(request)
  File "C:\Users\bayro\AppData\Roaming\Python\Python310\site-packages\django\core\handlers\base.py", line 197, in _get_response
    response = wrapped_callback(request, *callback_args, **callback_kwargs)
  File "C:\Users\bayro\AppData\Roaming\Python\Python310\site-packages\django\contrib\auth\decorators.py", line 60, in _view_wrapper
    return view_func(request, *args, **kwargs)
  File "C:\Users\bayro\Desktop\IngSoftware\career_roadmap\roadmap\views.py", line 18, in chat
    response = chatbot.get_response(user_input, chat_history)
  File "C:\Users\bayro\Desktop\IngSoftware\career_roadmap\roadmap\chatbot.py", line 23, in get_response
    response = self.generate_recommendation(chat_history)
  File "C:\Users\bayro\Desktop\IngSoftware\career_roadmap\roadmap\chatbot.py", line 27, in generate_recommendation
    client = OpenAI(api_key=os.getenv("openai_apikey"))
  File "C:\Users\bayro\AppData\Roaming\Python\Python310\site-packages\openai\_client.py", line 105, in __init__
    raise OpenAIError(
openai.OpenAIError: The api_key client option must be set either by passing api_key to the client or by setting the OPENAI_API_KEY environment variable
Internal Server Error: /chat/
Traceback (most recent call last):
  File "C:\Users\bayro\AppData\Roaming\Python\Python310\site-packages\django\core\handlers\exception.py", line 55, in inner
    response = get_response(request)
  File "C:\Users\bayro\AppData\Roaming\Python\Python310\site-packages\django\core\handlers\base.py", line 197, in _get_response
    response = wrapped_callback(request, *callback_args, **callback_kwargs)
  File "C:\Users\bayro\AppData\Roaming\Python\Python310\site-packages\django\contrib\auth\decorators.py", line 60, in _view_wrapper
    return view_func(request, *args, **kwargs)
  File "C:\Users\bayro\Desktop\IngSoftware\career_roadmap\roadmap\views.py", line 18, in chat
    response = chatbot.get_response(user_input, chat_history)
  File "C:\Users\bayro\Desktop\IngSoftware\career_roadmap\roadmap\chatbot.py", line 23, in get_response
    response = self.generate_recommendation(chat_history)
  File "C:\Users\bayro\Desktop\IngSoftware\career_roadmap\roadmap\chatbot.py", line 27, in generate_recommendation
    client = OpenAI(api_key=os.getenv("openai_apikey"))
  File "C:\Users\bayro\AppData\Roaming\Python\Python310\site-packages\openai\_client.py", line 105, in __init__
    raise OpenAIError(
openai.OpenAIError: The api_key client option must be set either by passing api_key to the client or by setting the OPENAI_API_KEY environment variable
Internal Server Error: /chat/
Traceback (most recent call last):
  File "C:\Users\bayro\AppData\Roaming\Python\Python310\site-packages\django\core\handlers\exception.py", line 55, in inner
    response = get_response(request)
  File "C:\Users\bayro\AppData\Roaming\Python\Python310\site-packages\django\core\handlers\base.py", line 197, in _get_response
    response = wrapped_callback(request, *callback_args, **callback_kwargs)
  File "C:\Users\bayro\AppData\Roaming\Python\Python310\site-packages\django\contrib\auth\decorators.py", line 60, in _view_wrapper
    return view_func(request, *args, **kwargs)
  File "C:\Users\bayro\Desktop\IngSoftware\career_roadmap\roadmap\views.py", line 18, in chat
    response = chatbot.get_response(user_input, chat_history)
  File "C:\Users\bayro\Desktop\IngSoftware\career_roadmap\roadmap\chatbot.py", line 23, in get_response
    response = self.generate_recommendation(chat_history)
  File "C:\Users\bayro\Desktop\IngSoftware\career_roadmap\roadmap\chatbot.py", line 27, in generate_recommendation
    client = OpenAI(api_key=os.getenv("openai_apikey"))
  File "C:\Users\bayro\AppData\Roaming\Python\Python310\site-packages\openai\_client.py", line 105, in __init__
    raise OpenAIError(
openai.OpenAIError: The api_key client option must be set either by passing api_key to the client or by setting the OPENAI_API_KEY environment variable
Internal Server Error: /roadmap/
Traceback (most recent call last):
  File "C:\Users\bayro\AppData\Roaming\Python\Python310\site-packages\django\core\handlers\exception.py", line 55, in inner
    response = get_response(request)
  File "C:\Users\bayro\AppData\Roaming\Python\Python310\site-packages\django\core\handlers\base.py", line 197, in _get_response
    response = wrapped_callback(request, *callback_args, **callback_kwargs)
  File "C:\Users\bayro\AppData\Roaming\Python\Python310\site-packages\django\contrib\auth\decorators.py", line 60, in _view_wrapper
    return view_func(request, *args, **kwargs)
  File "C:\Users\bayro\Desktop\IngSoftware\career_roadmap\roadmap\views.py", line 31, in roadmap
    return render(request, 'roadmap/roadmap.html', {'profile': profile})
  File "C:\Users\bayro\AppData\Roaming\Python\Python310\site-packages\django\shortcuts.py", line 25, in render
    content = loader.render_to_string(template_name, context, request, using=using)
  File "C:\Users\bayro\AppData\Roaming\Python\Python310\site-packages\django\template\loader.py", line 62, in render_to_string
    return template.render(context, request)
  File "C:\Users\bayro\AppData\Roaming\Python\Python310\site-packages\django\template\backends\django.py", line 107, in render
    return self.template.render(context)
  File "C:\Users\bayro\AppData\Roaming\Python\Python310\site-packages\django\template\base.py", line 171, in render
    return self._render(context)
  File "C:\Users\bayro\AppData\Roaming\Python\Python310\site-packages\django\template\base.py", line 163, in _render
    return self.nodelist.render(context)
  File "C:\Users\bayro\AppData\Roaming\Python\Python310\site-packages\django\template\base.py", line 1008, in render
    return SafeString("".join([node.render_annotated(context) for node in self]))
  File "C:\Users\bayro\AppData\Roaming\Python\Python310\site-packages\django\template\base.py", line 1008, in <listcomp>
    return SafeString("".join([node.render_annotated(context) for node in self]))
  File "C:\Users\bayro\AppData\Roaming\Python\Python310\site-packages\django\template\base.py", line 969, in render_annotated
    return self.render(context)
  File "C:\Users\bayro\AppData\Roaming\Python\Python310\site-packages\django\template\loader_tags.py", line 159, in render
    return compiled_parent._render(context)
  File "C:\Users\bayro\AppData\Roaming\Python\Python310\site-packages\django\template\base.py", line 163, in _render
    return self.nodelist.render(context)
  File "C:\Users\bayro\AppData\Roaming\Python\Python310\site-packages\django\template\base.py", line 1008, in render
    return SafeString("".join([node.render_annotated(context) for node in self]))
  File "C:\Users\bayro\AppData\Roaming\Python\Python310\site-packages\django\template\base.py", line 1008, in <listcomp>
    return SafeString("".join([node.render_annotated(context) for node in self]))
  File "C:\Users\bayro\AppData\Roaming\Python\Python310\site-packages\django\template\base.py", line 969, in render_annotated
    return self.render(context)
  File "C:\Users\bayro\AppData\Roaming\Python\Python310\site-packages\django\template\loader_tags.py", line 65, in render
    result = block.nodelist.render(context)
  File "C:\Users\bayro\AppData\Roaming\Python\Python310\site-packages\django\template\base.py", line 1008, in render
    return SafeString("".join([node.render_annotated(context) for node in self]))
  File "C:\Users\bayro\AppData\Roaming\Python\Python310\site-packages\django\template\base.py", line 1008, in <listcomp>
    return SafeString("".join([node.render_annotated(context) for node in self]))
  File "C:\Users\bayro\AppData\Roaming\Python\Python310\site-packages\django\template\base.py", line 969, in render_annotated
    return self.render(context)
  File "C:\Users\bayro\AppData\Roaming\Python\Python310\site-packages\django\template\defaulttags.py", line 480, in render
    url = reverse(view_name, args=args, kwargs=kwargs, current_app=current_app)
  File "C:\Users\bayro\AppData\Roaming\Python\Python310\site-packages\django\urls\base.py", line 88, in reverse
    return resolver._reverse_with_prefix(view, prefix, *args, **kwargs)
  File "C:\Users\bayro\AppData\Roaming\Python\Python310\site-packages\django\urls\resolvers.py", line 831, in _reverse_with_prefix
    raise NoReverseMatch(msg)
django.urls.exceptions.NoReverseMatch: Reverse for 'edit_profile' not found. 'edit_profile' is not a valid view function or pattern name.
Internal Server Error: /roadmap/
Traceback (most recent call last):
  File "C:\Users\bayro\AppData\Roaming\Python\Python310\site-packages\django\core\handlers\exception.py", line 55, in inner
    response = get_response(request)
  File "C:\Users\bayro\AppData\Roaming\Python\Python310\site-packages\django\core\handlers\base.py", line 197, in _get_response
    response = wrapped_callback(request, *callback_args, **callback_kwargs)
  File "C:\Users\bayro\AppData\Roaming\Python\Python310\site-packages\django\contrib\auth\decorators.py", line 60, in _view_wrapper
    return view_func(request, *args, **kwargs)
  File "C:\Users\bayro\Desktop\IngSoftware\career_roadmap\roadmap\views.py", line 31, in roadmap
    return render(request, 'roadmap/roadmap.html', {'profile': profile})
  File "C:\Users\bayro\AppData\Roaming\Python\Python310\site-packages\django\shortcuts.py", line 25, in render
    content = loader.render_to_string(template_name, context, request, using=using)
  File "C:\Users\bayro\AppData\Roaming\Python\Python310\site-packages\django\template\loader.py", line 62, in render_to_string
    return template.render(context, request)
  File "C:\Users\bayro\AppData\Roaming\Python\Python310\site-packages\django\template\backends\django.py", line 107, in render
    return self.template.render(context)
  File "C:\Users\bayro\AppData\Roaming\Python\Python310\site-packages\django\template\base.py", line 171, in render
    return self._render(context)
  File "C:\Users\bayro\AppData\Roaming\Python\Python310\site-packages\django\template\base.py", line 163, in _render
    return self.nodelist.render(context)
  File "C:\Users\bayro\AppData\Roaming\Python\Python310\site-packages\django\template\base.py", line 1008, in render
    return SafeString("".join([node.render_annotated(context) for node in self]))
  File "C:\Users\bayro\AppData\Roaming\Python\Python310\site-packages\django\template\base.py", line 1008, in <listcomp>
    return SafeString("".join([node.render_annotated(context) for node in self]))
  File "C:\Users\bayro\AppData\Roaming\Python\Python310\site-packages\django\template\base.py", line 969, in render_annotated
    return self.render(context)
  File "C:\Users\bayro\AppData\Roaming\Python\Python310\site-packages\django\template\loader_tags.py", line 159, in render
    return compiled_parent._render(context)
  File "C:\Users\bayro\AppData\Roaming\Python\Python310\site-packages\django\template\base.py", line 163, in _render
    return self.nodelist.render(context)
  File "C:\Users\bayro\AppData\Roaming\Python\Python310\site-packages\django\template\base.py", line 1008, in render
    return SafeString("".join([node.render_annotated(context) for node in self]))
  File "C:\Users\bayro\AppData\Roaming\Python\Python310\site-packages\django\template\base.py", line 1008, in <listcomp>
    return SafeString("".join([node.render_annotated(context) for node in self]))
  File "C:\Users\bayro\AppData\Roaming\Python\Python310\site-packages\django\template\base.py", line 969, in render_annotated
    return self.render(context)
  File "C:\Users\bayro\AppData\Roaming\Python\Python310\site-packages\django\template\loader_tags.py", line 65, in render
    result = block.nodelist.render(context)
  File "C:\Users\bayro\AppData\Roaming\Python\Python310\site-packages\django\template\base.py", line 1008, in render
    return SafeString("".join([node.render_annotated(context) for node in self]))
  File "C:\Users\bayro\AppData\Roaming\Python\Python310\site-packages\django\template\base.py", line 1008, in <listcomp>
    return SafeString("".join([node.render_annotated(context) for node in self]))
  File "C:\Users\bayro\AppData\Roaming\Python\Python310\site-packages\django\template\base.py", line 969, in render_annotated
    return self.render(context)
  File "C:\Users\bayro\AppData\Roaming\Python\Python310\site-packages\django\template\defaulttags.py", line 480, in render
    url = reverse(view_name, args=args, kwargs=kwargs, current_app=current_app)
  File "C:\Users\bayro\AppData\Roaming\Python\Python310\site-packages\django\urls\base.py", line 88, in reverse
    return resolver._reverse_with_prefix(view, prefix, *args, **kwargs)
  File "C:\Users\bayro\AppData\Roaming\Python\Python310\site-packages\django\urls\resolvers.py", line 831, in _reverse_with_prefix
    raise NoReverseMatch(msg)
django.urls.exceptions.NoReverseMatch: Reverse for 'editar_perfil' not found. 'editar_perfil' is not a valid view function or pattern name.
Internal Server Error: /roadmap/
Traceback (most recent call last):
  File "C:\Users\bayro\AppData\Roaming\Python\Python310\site-packages\django\core\handlers\exception.py", line 55, in inner
    response = get_response(request)
  File "C:\Users\bayro\AppData\Roaming\Python\Python310\site-packages\django\core\handlers\base.py", line 197, in _get_response
    response = wrapped_callback(request, *callback_args, **callback_kwargs)
  File "C:\Users\bayro\AppData\Roaming\Python\Python310\site-packages\django\contrib\auth\decorators.py", line 60, in _view_wrapper
    return view_func(request, *args, **kwargs)
  File "C:\Users\bayro\Desktop\IngSoftware\career_roadmap\roadmap\views.py", line 31, in roadmap
    return render(request, 'roadmap/roadmap.html', {'profile': profile})
  File "C:\Users\bayro\AppData\Roaming\Python\Python310\site-packages\django\shortcuts.py", line 25, in render
    content = loader.render_to_string(template_name, context, request, using=using)
  File "C:\Users\bayro\AppData\Roaming\Python\Python310\site-packages\django\template\loader.py", line 62, in render_to_string
    return template.render(context, request)
  File "C:\Users\bayro\AppData\Roaming\Python\Python310\site-packages\django\template\backends\django.py", line 107, in render
    return self.template.render(context)
  File "C:\Users\bayro\AppData\Roaming\Python\Python310\site-packages\django\template\base.py", line 171, in render
    return self._render(context)
  File "C:\Users\bayro\AppData\Roaming\Python\Python310\site-packages\django\template\base.py", line 163, in _render
    return self.nodelist.render(context)
  File "C:\Users\bayro\AppData\Roaming\Python\Python310\site-packages\django\template\base.py", line 1008, in render
    return SafeString("".join([node.render_annotated(context) for node in self]))
  File "C:\Users\bayro\AppData\Roaming\Python\Python310\site-packages\django\template\base.py", line 1008, in <listcomp>
    return SafeString("".join([node.render_annotated(context) for node in self]))
  File "C:\Users\bayro\AppData\Roaming\Python\Python310\site-packages\django\template\base.py", line 969, in render_annotated
    return self.render(context)
  File "C:\Users\bayro\AppData\Roaming\Python\Python310\site-packages\django\template\loader_tags.py", line 159, in render
    return compiled_parent._render(context)
  File "C:\Users\bayro\AppData\Roaming\Python\Python310\site-packages\django\template\base.py", line 163, in _render
    return self.nodelist.render(context)
  File "C:\Users\bayro\AppData\Roaming\Python\Python310\site-packages\django\template\base.py", line 1008, in render
    return SafeString("".join([node.render_annotated(context) for node in self]))
  File "C:\Users\bayro\AppData\Roaming\Python\Python310\site-packages\django\template\base.py", line 1008, in <listcomp>
    return SafeString("".join([node.render_annotated(context) for node in self]))
  File "C:\Users\bayro\AppData\Roaming\Python\Python310\site-packages\django\template\base.py", line 969, in render_annotated
    return self.render(context)
  File "C:\Users\bayro\AppData\Roaming\Python\Python310\site-packages\django\template\loader_tags.py", line 65, in render
    result = block.nodelist.render(context)
  File "C:\Users\bayro\AppData\Roaming\Python\Python310\site-packages\django\template\base.py", line 1008, in render
    return SafeString("".join([node.render_annotated(context) for node in self]))
  File "C:\Users\bayro\AppData\Roaming\Python\Python310\site-packages\django\template\base.py", line 1008, in <listcomp>
    return SafeString("".join([node.render_annotated(context) for node in self]))
  File "C:\Users\bayro\AppData\Roaming\Python\Python310\site-packages\django\template\base.py", line 969, in render_annotated
    return self.render(context)
  File "C:\Users\bayro\AppData\Roaming\Python\Python310\site-packages\django\template\defaulttags.py", line 480, in render
    url = reverse(view_name, args=args, kwargs=kwargs, current_app=current_app)
  File "C:\Users\bayro\AppData\Roaming\Python\Python310\site-packages\django\urls\base.py", line 88, in reverse
    return resolver._reverse_with_prefix(view, prefix, *args, **kwargs)
  File "C:\Users\bayro\AppData\Roaming\Python\Python310\site-packages\django\urls\resolvers.py", line 831, in _reverse_with_prefix
    raise NoReverseMatch(msg)
django.urls.exceptions.NoReverseMatch: Reverse for 'editar_perfil' not found. 'editar_perfil' is not a valid view function or pattern name.
Internal Server Error: /roadmap/
Traceback (most recent call last):
  File "C:\Users\bayro\AppData\Roaming\Python\Python310\site-packages\django\core\handlers\exception.py", line 55, in inner
    response = get_response(request)
  File "C:\Users\bayro\AppData\Roaming\Python\Python310\site-packages\django\core\handlers\base.py", line 197, in _get_response
    response = wrapped_callback(request, *callback_args, **callback_kwargs)
  File "C:\Users\bayro\AppData\Roaming\Python\Python310\site-packages\django\contrib\auth\decorators.py", line 60, in _view_wrapper
    return view_func(request, *args, **kwargs)
  File "C:\Users\bayro\Desktop\IngSoftware\career_roadmap\roadmap\views.py", line 31, in roadmap
    return render(request, 'roadmap/roadmap.html', {'profile': profile})
  File "C:\Users\bayro\AppData\Roaming\Python\Python310\site-packages\django\shortcuts.py", line 25, in render
    content = loader.render_to_string(template_name, context, request, using=using)
  File "C:\Users\bayro\AppData\Roaming\Python\Python310\site-packages\django\template\loader.py", line 62, in render_to_string
    return template.render(context, request)
  File "C:\Users\bayro\AppData\Roaming\Python\Python310\site-packages\django\template\backends\django.py", line 107, in render
    return self.template.render(context)
  File "C:\Users\bayro\AppData\Roaming\Python\Python310\site-packages\django\template\base.py", line 171, in render
    return self._render(context)
  File "C:\Users\bayro\AppData\Roaming\Python\Python310\site-packages\django\template\base.py", line 163, in _render
    return self.nodelist.render(context)
  File "C:\Users\bayro\AppData\Roaming\Python\Python310\site-packages\django\template\base.py", line 1008, in render
    return SafeString("".join([node.render_annotated(context) for node in self]))
  File "C:\Users\bayro\AppData\Roaming\Python\Python310\site-packages\django\template\base.py", line 1008, in <listcomp>
    return SafeString("".join([node.render_annotated(context) for node in self]))
  File "C:\Users\bayro\AppData\Roaming\Python\Python310\site-packages\django\template\base.py", line 969, in render_annotated
    return self.render(context)
  File "C:\Users\bayro\AppData\Roaming\Python\Python310\site-packages\django\template\loader_tags.py", line 159, in render
    return compiled_parent._render(context)
  File "C:\Users\bayro\AppData\Roaming\Python\Python310\site-packages\django\template\base.py", line 163, in _render
    return self.nodelist.render(context)
  File "C:\Users\bayro\AppData\Roaming\Python\Python310\site-packages\django\template\base.py", line 1008, in render
    return SafeString("".join([node.render_annotated(context) for node in self]))
  File "C:\Users\bayro\AppData\Roaming\Python\Python310\site-packages\django\template\base.py", line 1008, in <listcomp>
    return SafeString("".join([node.render_annotated(context) for node in self]))
  File "C:\Users\bayro\AppData\Roaming\Python\Python310\site-packages\django\template\base.py", line 969, in render_annotated
    return self.render(context)
  File "C:\Users\bayro\AppData\Roaming\Python\Python310\site-packages\django\template\loader_tags.py", line 65, in render
    result = block.nodelist.render(context)
  File "C:\Users\bayro\AppData\Roaming\Python\Python310\site-packages\django\template\base.py", line 1008, in render
    return SafeString("".join([node.render_annotated(context) for node in self]))
  File "C:\Users\bayro\AppData\Roaming\Python\Python310\site-packages\django\template\base.py", line 1008, in <listcomp>
    return SafeString("".join([node.render_annotated(context) for node in self]))
  File "C:\Users\bayro\AppData\Roaming\Python\Python310\site-packages\django\template\base.py", line 969, in render_annotated
    return self.render(context)
  File "C:\Users\bayro\AppData\Roaming\Python\Python310\site-packages\django\template\defaulttags.py", line 480, in render
    url = reverse(view_name, args=args, kwargs=kwargs, current_app=current_app)
  File "C:\Users\bayro\AppData\Roaming\Python\Python310\site-packages\django\urls\base.py", line 88, in reverse
    return resolver._reverse_with_prefix(view, prefix, *args, **kwargs)
  File "C:\Users\bayro\AppData\Roaming\Python\Python310\site-packages\django\urls\resolvers.py", line 831, in _reverse_with_prefix
    raise NoReverseMatch(msg)
django.urls.exceptions.NoReverseMatch: Reverse for 'editar_perfil' not found. 'editar_perfil' is not a valid view function or pattern name.
Internal Server Error: /roadmap/
Traceback (most recent call last):
  File "C:\Users\bayro\AppData\Roaming\Python\Python310\site-packages\django\core\handlers\exception.py", line 55, in inner
    response = get_response(request)
  File "C:\Users\bayro\AppData\Roaming\Python\Python310\site-packages\django\core\handlers\base.py", line 197, in _get_response
    response = wrapped_callback(request, *callback_args, **callback_kwargs)
  File "C:\Users\bayro\AppData\Roaming\Python\Python310\site-packages\django\contrib\auth\decorators.py", line 60, in _view_wrapper
    return view_func(request, *args, **kwargs)
  File "C:\Users\bayro\Desktop\IngSoftware\career_roadmap\roadmap\views.py", line 31, in roadmap
    return render(request, 'roadmap/roadmap.html', {'profile': profile})
  File "C:\Users\bayro\AppData\Roaming\Python\Python310\site-packages\django\shortcuts.py", line 25, in render
    content = loader.render_to_string(template_name, context, request, using=using)
  File "C:\Users\bayro\AppData\Roaming\Python\Python310\site-packages\django\template\loader.py", line 62, in render_to_string
    return template.render(context, request)
  File "C:\Users\bayro\AppData\Roaming\Python\Python310\site-packages\django\template\backends\django.py", line 107, in render
    return self.template.render(context)
  File "C:\Users\bayro\AppData\Roaming\Python\Python310\site-packages\django\template\base.py", line 171, in render
    return self._render(context)
  File "C:\Users\bayro\AppData\Roaming\Python\Python310\site-packages\django\template\base.py", line 163, in _render
    return self.nodelist.render(context)
  File "C:\Users\bayro\AppData\Roaming\Python\Python310\site-packages\django\template\base.py", line 1008, in render
    return SafeString("".join([node.render_annotated(context) for node in self]))
  File "C:\Users\bayro\AppData\Roaming\Python\Python310\site-packages\django\template\base.py", line 1008, in <listcomp>
    return SafeString("".join([node.render_annotated(context) for node in self]))
  File "C:\Users\bayro\AppData\Roaming\Python\Python310\site-packages\django\template\base.py", line 969, in render_annotated
    return self.render(context)
  File "C:\Users\bayro\AppData\Roaming\Python\Python310\site-packages\django\template\loader_tags.py", line 159, in render
    return compiled_parent._render(context)
  File "C:\Users\bayro\AppData\Roaming\Python\Python310\site-packages\django\template\base.py", line 163, in _render
    return self.nodelist.render(context)
  File "C:\Users\bayro\AppData\Roaming\Python\Python310\site-packages\django\template\base.py", line 1008, in render
    return SafeString("".join([node.render_annotated(context) for node in self]))
  File "C:\Users\bayro\AppData\Roaming\Python\Python310\site-packages\django\template\base.py", line 1008, in <listcomp>
    return SafeString("".join([node.render_annotated(context) for node in self]))
  File "C:\Users\bayro\AppData\Roaming\Python\Python310\site-packages\django\template\base.py", line 969, in render_annotated
    return self.render(context)
  File "C:\Users\bayro\AppData\Roaming\Python\Python310\site-packages\django\template\loader_tags.py", line 65, in render
    result = block.nodelist.render(context)
  File "C:\Users\bayro\AppData\Roaming\Python\Python310\site-packages\django\template\base.py", line 1008, in render
    return SafeString("".join([node.render_annotated(context) for node in self]))
  File "C:\Users\bayro\AppData\Roaming\Python\Python310\site-packages\django\template\base.py", line 1008, in <listcomp>
    return SafeString("".join([node.render_annotated(context) for node in self]))
  File "C:\Users\bayro\AppData\Roaming\Python\Python310\site-packages\django\template\base.py", line 969, in render_annotated
    return self.render(context)
  File "C:\Users\bayro\AppData\Roaming\Python\Python310\site-packages\django\template\defaulttags.py", line 480, in render
    url = reverse(view_name, args=args, kwargs=kwargs, current_app=current_app)
  File "C:\Users\bayro\AppData\Roaming\Python\Python310\site-packages\django\urls\base.py", line 88, in reverse
    return resolver._reverse_with_prefix(view, prefix, *args, **kwargs)
  File "C:\Users\bayro\AppData\Roaming\Python\Python310\site-packages\django\urls\resolvers.py", line 831, in _reverse_with_prefix
    raise NoReverseMatch(msg)
django.urls.exceptions.NoReverseMatch: Reverse for 'editar_perfil' not found. 'editar_perfil' is not a valid view function or pattern name.
Internal Server Error: /roadmap/
Traceback (most recent call last):
  File "C:\Users\bayro\AppData\Roaming\Python\Python310\site-packages\django\core\handlers\exception.py", line 55, in inner
    response = get_response(request)
  File "C:\Users\bayro\AppData\Roaming\Python\Python310\site-packages\django\core\handlers\base.py", line 197, in _get_response
    response = wrapped_callback(request, *callback_args, **callback_kwargs)
  File "C:\Users\bayro\AppData\Roaming\Python\Python310\site-packages\django\contrib\auth\decorators.py", line 60, in _view_wrapper
    return view_func(request, *args, **kwargs)
  File "C:\Users\bayro\Desktop\IngSoftware\career_roadmap\roadmap\views.py", line 31, in roadmap
    return render(request, 'roadmap/roadmap.html', {'profile': profile})
  File "C:\Users\bayro\AppData\Roaming\Python\Python310\site-packages\django\shortcuts.py", line 25, in render
    content = loader.render_to_string(template_name, context, request, using=using)
  File "C:\Users\bayro\AppData\Roaming\Python\Python310\site-packages\django\template\loader.py", line 62, in render_to_string
    return template.render(context, request)
  File "C:\Users\bayro\AppData\Roaming\Python\Python310\site-packages\django\template\backends\django.py", line 107, in render
    return self.template.render(context)
  File "C:\Users\bayro\AppData\Roaming\Python\Python310\site-packages\django\template\base.py", line 171, in render
    return self._render(context)
  File "C:\Users\bayro\AppData\Roaming\Python\Python310\site-packages\django\template\base.py", line 163, in _render
    return self.nodelist.render(context)
  File "C:\Users\bayro\AppData\Roaming\Python\Python310\site-packages\django\template\base.py", line 1008, in render
    return SafeString("".join([node.render_annotated(context) for node in self]))
  File "C:\Users\bayro\AppData\Roaming\Python\Python310\site-packages\django\template\base.py", line 1008, in <listcomp>
    return SafeString("".join([node.render_annotated(context) for node in self]))
  File "C:\Users\bayro\AppData\Roaming\Python\Python310\site-packages\django\template\base.py", line 969, in render_annotated
    return self.render(context)
  File "C:\Users\bayro\AppData\Roaming\Python\Python310\site-packages\django\template\loader_tags.py", line 159, in render
    return compiled_parent._render(context)
  File "C:\Users\bayro\AppData\Roaming\Python\Python310\site-packages\django\template\base.py", line 163, in _render
    return self.nodelist.render(context)
  File "C:\Users\bayro\AppData\Roaming\Python\Python310\site-packages\django\template\base.py", line 1008, in render
    return SafeString("".join([node.render_annotated(context) for node in self]))
  File "C:\Users\bayro\AppData\Roaming\Python\Python310\site-packages\django\template\base.py", line 1008, in <listcomp>
    return SafeString("".join([node.render_annotated(context) for node in self]))
  File "C:\Users\bayro\AppData\Roaming\Python\Python310\site-packages\django\template\base.py", line 969, in render_annotated
    return self.render(context)
  File "C:\Users\bayro\AppData\Roaming\Python\Python310\site-packages\django\template\loader_tags.py", line 65, in render
    result = block.nodelist.render(context)
  File "C:\Users\bayro\AppData\Roaming\Python\Python310\site-packages\django\template\base.py", line 1008, in render
    return SafeString("".join([node.render_annotated(context) for node in self]))
  File "C:\Users\bayro\AppData\Roaming\Python\Python310\site-packages\django\template\base.py", line 1008, in <listcomp>
    return SafeString("".join([node.render_annotated(context) for node in self]))
  File "C:\Users\bayro\AppData\Roaming\Python\Python310\site-packages\django\template\base.py", line 969, in render_annotated
    return self.render(context)
  File "C:\Users\bayro\AppData\Roaming\Python\Python310\site-packages\django\template\defaulttags.py", line 480, in render
    url = reverse(view_name, args=args, kwargs=kwargs, current_app=current_app)
  File "C:\Users\bayro\AppData\Roaming\Python\Python310\site-packages\django\urls\base.py", line 88, in reverse
    return resolver._reverse_with_prefix(view, prefix, *args, **kwargs)
  File "C:\Users\bayro\AppData\Roaming\Python\Python310\site-packages\django\urls\resolvers.py", line 831, in _reverse_with_prefix
    raise NoReverseMatch(msg)
django.urls.exceptions.NoReverseMatch: Reverse for 'editar_perfil' not found. 'editar_perfil' is not a valid view function or pattern name.
Internal Server Error: /roadmap/
Traceback (most recent call last):
  File "C:\Users\bayro\AppData\Roaming\Python\Python310\site-packages\django\core\handlers\exception.py", line 55, in inner
    response = get_response(request)
  File "C:\Users\bayro\AppData\Roaming\Python\Python310\site-packages\django\core\handlers\base.py", line 197, in _get_response
    response = wrapped_callback(request, *callback_args, **callback_kwargs)
  File "C:\Users\bayro\Desktop\IngSoftware\career_roadmap\roadmap\views.py", line 10, in home
    return render(request, 'roadmap/index.html')
  File "C:\Users\bayro\AppData\Roaming\Python\Python310\site-packages\django\shortcuts.py", line 25, in render
    content = loader.render_to_string(template_name, context, request, using=using)
  File "C:\Users\bayro\AppData\Roaming\Python\Python310\site-packages\django\template\loader.py", line 62, in render_to_string
    return template.render(context, request)
  File "C:\Users\bayro\AppData\Roaming\Python\Python310\site-packages\django\template\backends\django.py", line 107, in render
    return self.template.render(context)
  File "C:\Users\bayro\AppData\Roaming\Python\Python310\site-packages\django\template\base.py", line 171, in render
    return self._render(context)
  File "C:\Users\bayro\AppData\Roaming\Python\Python310\site-packages\django\template\base.py", line 163, in _render
    return self.nodelist.render(context)
  File "C:\Users\bayro\AppData\Roaming\Python\Python310\site-packages\django\template\base.py", line 1008, in render
    return SafeString("".join([node.render_annotated(context) for node in self]))
  File "C:\Users\bayro\AppData\Roaming\Python\Python310\site-packages\django\template\base.py", line 1008, in <listcomp>
    return SafeString("".join([node.render_annotated(context) for node in self]))
  File "C:\Users\bayro\AppData\Roaming\Python\Python310\site-packages\django\template\base.py", line 969, in render_annotated
    return self.render(context)
  File "C:\Users\bayro\AppData\Roaming\Python\Python310\site-packages\django\template\loader_tags.py", line 159, in render
    return compiled_parent._render(context)
  File "C:\Users\bayro\AppData\Roaming\Python\Python310\site-packages\django\template\base.py", line 163, in _render
    return self.nodelist.render(context)
  File "C:\Users\bayro\AppData\Roaming\Python\Python310\site-packages\django\template\base.py", line 1008, in render
    return SafeString("".join([node.render_annotated(context) for node in self]))
  File "C:\Users\bayro\AppData\Roaming\Python\Python310\site-packages\django\template\base.py", line 1008, in <listcomp>
    return SafeString("".join([node.render_annotated(context) for node in self]))
  File "C:\Users\bayro\AppData\Roaming\Python\Python310\site-packages\django\template\base.py", line 969, in render_annotated
    return self.render(context)
  File "C:\Users\bayro\AppData\Roaming\Python\Python310\site-packages\django\template\defaulttags.py", line 327, in render
    return nodelist.render(context)
  File "C:\Users\bayro\AppData\Roaming\Python\Python310\site-packages\django\template\base.py", line 1008, in render
    return SafeString("".join([node.render_annotated(context) for node in self]))
  File "C:\Users\bayro\AppData\Roaming\Python\Python310\site-packages\django\template\base.py", line 1008, in <listcomp>
    return SafeString("".join([node.render_annotated(context) for node in self]))
  File "C:\Users\bayro\AppData\Roaming\Python\Python310\site-packages\django\template\base.py", line 969, in render_annotated
    return self.render(context)
  File "C:\Users\bayro\AppData\Roaming\Python\Python310\site-packages\django\template\defaulttags.py", line 480, in render
    url = reverse(view_name, args=args, kwargs=kwargs, current_app=current_app)
  File "C:\Users\bayro\AppData\Roaming\Python\Python310\site-packages\django\urls\base.py", line 88, in reverse
    return resolver._reverse_with_prefix(view, prefix, *args, **kwargs)
  File "C:\Users\bayro\AppData\Roaming\Python\Python310\site-packages\django\urls\resolvers.py", line 831, in _reverse_with_prefix
    raise NoReverseMatch(msg)
django.urls.exceptions.NoReverseMatch: Reverse for 'roadmap' with no arguments not found. 1 pattern(s) tried: ['roadmap/roadmap/(?P<user_id>[0-9]+)/\\Z']
Internal Server Error: /roadmap/editar-perfil/
Traceback (most recent call last):
  File "C:\Users\bayro\AppData\Roaming\Python\Python310\site-packages\django\core\handlers\exception.py", line 55, in inner
    response = get_response(request)
  File "C:\Users\bayro\AppData\Roaming\Python\Python310\site-packages\django\core\handlers\base.py", line 197, in _get_response
    response = wrapped_callback(request, *callback_args, **callback_kwargs)
  File "C:\Users\bayro\AppData\Roaming\Python\Python310\site-packages\django\contrib\auth\decorators.py", line 60, in _view_wrapper
    return view_func(request, *args, **kwargs)
  File "C:\Users\bayro\Desktop\IngSoftware\career_roadmap\roadmap\views.py", line 63, in edit_profile
    form = UserProfileForm(request.POST, instance=profile)
NameError: name 'UserProfileForm' is not defined. Did you mean: 'UserProfile'?
Internal Server Error: /roadmap/editar-perfil/
Traceback (most recent call last):
  File "C:\Users\bayro\AppData\Roaming\Python\Python310\site-packages\django\core\handlers\exception.py", line 55, in inner
    response = get_response(request)
  File "C:\Users\bayro\AppData\Roaming\Python\Python310\site-packages\django\core\handlers\base.py", line 197, in _get_response
    response = wrapped_callback(request, *callback_args, **callback_kwargs)
  File "C:\Users\bayro\AppData\Roaming\Python\Python310\site-packages\django\contrib\auth\decorators.py", line 60, in _view_wrapper
    return view_func(request, *args, **kwargs)
  File "C:\Users\bayro\Desktop\IngSoftware\career_roadmap\roadmap\views.py", line 67, in edit_profile
    return redirect('roadmap')  # Redirige a la vista del roadmap
  File "C:\Users\bayro\AppData\Roaming\Python\Python310\site-packages\django\shortcuts.py", line 49, in redirect
    return redirect_class(resolve_url(to, *args, **kwargs))
  File "C:\Users\bayro\AppData\Roaming\Python\Python310\site-packages\django\shortcuts.py", line 180, in resolve_url
    return reverse(to, args=args, kwargs=kwargs)
  File "C:\Users\bayro\AppData\Roaming\Python\Python310\site-packages\django\urls\base.py", line 88, in reverse
    return resolver._reverse_with_prefix(view, prefix, *args, **kwargs)
  File "C:\Users\bayro\AppData\Roaming\Python\Python310\site-packages\django\urls\resolvers.py", line 831, in _reverse_with_prefix
    raise NoReverseMatch(msg)
django.urls.exceptions.NoReverseMatch: Reverse for 'roadmap' with no arguments not found. 1 pattern(s) tried: ['roadmap/roadmap/(?P<user_id>[0-9]+)/\\Z']
Internal Server Error: /roadmap/editar-perfil/
Traceback (most recent call last):
  File "C:\Users\bayro\AppData\Roaming\Python\Python310\site-packages\django\core\handlers\exception.py", line 55, in inner
    response = get_response(request)
  File "C:\Users\bayro\AppData\Roaming\Python\Python310\site-packages\django\core\handlers\base.py", line 197, in _get_response
    response = wrapped_callback(request, *callback_args, **callback_kwargs)
  File "C:\Users\bayro\AppData\Roaming\Python\Python310\site-packages\django\contrib\auth\decorators.py", line 60, in _view_wrapper
    return view_func(request, *args, **kwargs)
  File "C:\Users\bayro\Desktop\IngSoftware\career_roadmap\roadmap\views.py", line 67, in edit_profile
    return redirect('roadmap')  # Redirige a la vista del roadmap
  File "C:\Users\bayro\AppData\Roaming\Python\Python310\site-packages\django\shortcuts.py", line 49, in redirect
    return redirect_class(resolve_url(to, *args, **kwargs))
  File "C:\Users\bayro\AppData\Roaming\Python\Python310\site-packages\django\shortcuts.py", line 180, in resolve_url
    return reverse(to, args=args, kwargs=kwargs)
  File "C:\Users\bayro\AppData\Roaming\Python\Python310\site-packages\django\urls\base.py", line 88, in reverse
    return resolver._reverse_with_prefix(view, prefix, *args, **kwargs)
  File "C:\Users\bayro\AppData\Roaming\Python\Python310\site-packages\django\urls\resolvers.py", line 831, in _reverse_with_prefix
    raise NoReverseMatch(msg)
django.urls.exceptions.NoReverseMatch: Reverse for 'roadmap' with no arguments not found. 1 pattern(s) tried: ['roadmap/roadmap/(?P<user_id>[0-9]+)/\\Z']
Internal Server Error: /chat/
Traceback (most recent call last):
  File "C:\Users\bayro\AppData\Roaming\Python\Python310\site-packages\django\core\handlers\exception.py", line 55, in inner
    response = get_response(request)
  File "C:\Users\bayro\AppData\Roaming\Python\Python310\site-packages\django\core\handlers\base.py", line 197, in _get_response
    response = wrapped_callback(request, *callback_args, **callback_kwargs)
  File "C:\Users\bayro\AppData\Roaming\Python\Python310\site-packages\django\contrib\auth\decorators.py", line 60, in _view_wrapper
    return view_func(request, *args, **kwargs)
  File "C:\Users\bayro\Desktop\IngSoftware\career_roadmap\roadmap\views.py", line 19, in chat
    response = chatbot.get_response(user_input, chat_history)
  File "C:\Users\bayro\Desktop\IngSoftware\career_roadmap\roadmap\chatbot.py", line 25, in get_response
    response = self.generate_recommendation(chat_history)
  File "C:\Users\bayro\Desktop\IngSoftware\career_roadmap\roadmap\chatbot.py", line 36, in generate_recommendation
    response = openai.ChatCompletion.create(
  File "C:\Users\bayro\AppData\Roaming\Python\Python310\site-packages\openai\lib\_old_api.py", line 39, in __call__
    raise APIRemovedInV1(symbol=self._symbol)
openai.lib._old_api.APIRemovedInV1: 

You tried to access openai.ChatCompletion, but this is no longer supported in openai>=1.0.0 - see the README at https://github.com/openai/openai-python for the API.

You can run `openai migrate` to automatically upgrade your codebase to use the 1.0.0 interface. 

Alternatively, you can pin your installation to the old version, e.g. `pip install openai==0.28`

A detailed migration guide is available here: https://github.com/openai/openai-python/discussions/742

Internal Server Error: /chat/
Traceback (most recent call last):
  File "C:\Users\bayro\AppData\Roaming\Python\Python310\site-packages\django\core\handlers\exception.py", line 55, in inner
    response = get_response(request)
  File "C:\Users\bayro\AppData\Roaming\Python\Python310\site-packages\django\core\handlers\base.py", line 197, in _get_response
    response = wrapped_callback(request, *callback_args, **callback_kwargs)
  File "C:\Users\bayro\AppData\Roaming\Python\Python310\site-packages\django\contrib\auth\decorators.py", line 60, in _view_wrapper
    return view_func(request, *args, **kwargs)
  File "C:\Users\bayro\Desktop\IngSoftware\career_roadmap\roadmap\views.py", line 19, in chat
    response = chatbot.get_response(user_input, chat_history)
  File "C:\Users\bayro\Desktop\IngSoftware\career_roadmap\roadmap\chatbot.py", line 25, in get_response
    response = self.generate_recommendation(chat_history)
  File "C:\Users\bayro\Desktop\IngSoftware\career_roadmap\roadmap\chatbot.py", line 36, in generate_recommendation
    response = openai.ChatCompletion.create(
  File "C:\Users\bayro\AppData\Roaming\Python\Python310\site-packages\openai\lib\_old_api.py", line 39, in __call__
    raise APIRemovedInV1(symbol=self._symbol)
openai.lib._old_api.APIRemovedInV1: 

You tried to access openai.ChatCompletion, but this is no longer supported in openai>=1.0.0 - see the README at https://github.com/openai/openai-python for the API.

You can run `openai migrate` to automatically upgrade your codebase to use the 1.0.0 interface. 

Alternatively, you can pin your installation to the old version, e.g. `pip install openai==0.28`

A detailed migration guide is available here: https://github.com/openai/openai-python/discussions/742

Internal Server Error: /roadmap/editar-perfil/
Traceback (most recent call last):
  File "C:\Users\bayro\AppData\Roaming\Python\Python310\site-packages\django\core\handlers\exception.py", line 55, in inner
    response = get_response(request)
  File "C:\Users\bayro\AppData\Roaming\Python\Python310\site-packages\django\core\handlers\base.py", line 197, in _get_response
    response = wrapped_callback(request, *callback_args, **callback_kwargs)
  File "C:\Users\bayro\AppData\Roaming\Python\Python310\site-packages\django\contrib\auth\decorators.py", line 60, in _view_wrapper
    return view_func(request, *args, **kwargs)
  File "C:\Users\bayro\Desktop\IngSoftware\career_roadmap\roadmap\views.py", line 70, in edit_profile
    return render(request, 'roadmap/edit_profile.html', {'form': form})
  File "C:\Users\bayro\AppData\Roaming\Python\Python310\site-packages\django\shortcuts.py", line 25, in render
    content = loader.render_to_string(template_name, context, request, using=using)
  File "C:\Users\bayro\AppData\Roaming\Python\Python310\site-packages\django\template\loader.py", line 61, in render_to_string
    template = get_template(template_name, using=using)
  File "C:\Users\bayro\AppData\Roaming\Python\Python310\site-packages\django\template\loader.py", line 19, in get_template
    raise TemplateDoesNotExist(template_name, chain=chain)
django.template.exceptions.TemplateDoesNotExist: roadmap/edit_profile.html
Internal Server Error: /roadmap/editar-perfil/
Traceback (most recent call last):
  File "C:\Users\bayro\AppData\Roaming\Python\Python310\site-packages\django\core\handlers\exception.py", line 55, in inner
    response = get_response(request)
  File "C:\Users\bayro\AppData\Roaming\Python\Python310\site-packages\django\core\handlers\base.py", line 197, in _get_response
    response = wrapped_callback(request, *callback_args, **callback_kwargs)
  File "C:\Users\bayro\AppData\Roaming\Python\Python310\site-packages\django\contrib\auth\decorators.py", line 60, in _view_wrapper
    return view_func(request, *args, **kwargs)
  File "C:\Users\bayro\Desktop\IngSoftware\career_roadmap\roadmap\views.py", line 70, in edit_profile
    return render(request, 'roadmap/edit_profile.html', {'form': form})
  File "C:\Users\bayro\AppData\Roaming\Python\Python310\site-packages\django\shortcuts.py", line 25, in render
    content = loader.render_to_string(template_name, context, request, using=using)
  File "C:\Users\bayro\AppData\Roaming\Python\Python310\site-packages\django\template\loader.py", line 61, in render_to_string
    template = get_template(template_name, using=using)
  File "C:\Users\bayro\AppData\Roaming\Python\Python310\site-packages\django\template\loader.py", line 19, in get_template
    raise TemplateDoesNotExist(template_name, chain=chain)
django.template.exceptions.TemplateDoesNotExist: roadmap/edit_profile.html
Internal Server Error: /roadmap/editar-perfil/
Traceback (most recent call last):
  File "C:\Users\bayro\AppData\Roaming\Python\Python310\site-packages\django\core\handlers\exception.py", line 55, in inner
    response = get_response(request)
  File "C:\Users\bayro\AppData\Roaming\Python\Python310\site-packages\django\core\handlers\base.py", line 197, in _get_response
    response = wrapped_callback(request, *callback_args, **callback_kwargs)
  File "C:\Users\bayro\AppData\Roaming\Python\Python310\site-packages\django\contrib\auth\decorators.py", line 60, in _view_wrapper
    return view_func(request, *args, **kwargs)
  File "C:\Users\bayro\Desktop\IngSoftware\career_roadmap\roadmap\views.py", line 70, in edit_profile
    return render(request, 'roadmap/edit_profile.html', {'form': form})
  File "C:\Users\bayro\AppData\Roaming\Python\Python310\site-packages\django\shortcuts.py", line 25, in render
    content = loader.render_to_string(template_name, context, request, using=using)
  File "C:\Users\bayro\AppData\Roaming\Python\Python310\site-packages\django\template\loader.py", line 61, in render_to_string
    template = get_template(template_name, using=using)
  File "C:\Users\bayro\AppData\Roaming\Python\Python310\site-packages\django\template\loader.py", line 19, in get_template
    raise TemplateDoesNotExist(template_name, chain=chain)
django.template.exceptions.TemplateDoesNotExist: roadmap/edit_profile.html
Internal Server Error: /roadmap/editar-perfil/
Traceback (most recent call last):
  File "C:\Users\bayro\AppData\Roaming\Python\Python310\site-packages\django\core\handlers\exception.py", line 55, in inner
    response = get_response(request)
  File "C:\Users\bayro\AppData\Roaming\Python\Python310\site-packages\django\core\handlers\base.py", line 197, in _get_response
    response = wrapped_callback(request, *callback_args, **callback_kwargs)
  File "C:\Users\bayro\AppData\Roaming\Python\Python310\site-packages\django\contrib\auth\decorators.py", line 60, in _view_wrapper
    return view_func(request, *args, **kwargs)
  File "C:\Users\bayro\Desktop\IngSoftware\career_roadmap\roadmap\views.py", line 70, in edit_profile
    return render(request, 'roadmap/edit_profile.html', {'form': form})
  File "C:\Users\bayro\AppData\Roaming\Python\Python310\site-packages\django\shortcuts.py", line 25, in render
    content = loader.render_to_string(template_name, context, request, using=using)
  File "C:\Users\bayro\AppData\Roaming\Python\Python310\site-packages\django\template\loader.py", line 61, in render_to_string
    template = get_template(template_name, using=using)
  File "C:\Users\bayro\AppData\Roaming\Python\Python310\site-packages\django\template\loader.py", line 19, in get_template
    raise TemplateDoesNotExist(template_name, chain=chain)
django.template.exceptions.TemplateDoesNotExist: roadmap/edit_profile.html
Internal Server Error: /roadmap/editar-perfil/
Traceback (most recent call last):
  File "C:\Users\bayro\AppData\Roaming\Python\Python310\site-packages\django\core\handlers\exception.py", line 55, in inner
    response = get_response(request)
  File "C:\Users\bayro\AppData\Roaming\Python\Python310\site-packages\django\core\handlers\base.py", line 197, in _get_response
    response = wrapped_callback(request, *callback_args, **callback_kwargs)
  File "C:\Users\bayro\AppData\Roaming\Python\Python310\site-packages\django\contrib\auth\decorators.py", line 60, in _view_wrapper
    return view_func(request, *args, **kwargs)
  File "C:\Users\bayro\Desktop\IngSoftware\career_roadmap\roadmap\views.py", line 70, in edit_profile
    return render(request, 'roadmap/edit_profile.html', {'form': form})
  File "C:\Users\bayro\AppData\Roaming\Python\Python310\site-packages\django\shortcuts.py", line 25, in render
    content = loader.render_to_string(template_name, context, request, using=using)
  File "C:\Users\bayro\AppData\Roaming\Python\Python310\site-packages\django\template\loader.py", line 61, in render_to_string
    template = get_template(template_name, using=using)
  File "C:\Users\bayro\AppData\Roaming\Python\Python310\site-packages\django\template\loader.py", line 19, in get_template
    raise TemplateDoesNotExist(template_name, chain=chain)
django.template.exceptions.TemplateDoesNotExist: roadmap/edit_profile.html
Internal Server Error: /roadmap/editar-perfil/
Traceback (most recent call last):
  File "C:\Users\bayro\AppData\Roaming\Python\Python310\site-packages\django\core\handlers\exception.py", line 55, in inner
    response = get_response(request)
  File "C:\Users\bayro\AppData\Roaming\Python\Python310\site-packages\django\core\handlers\base.py", line 197, in _get_response
    response = wrapped_callback(request, *callback_args, **callback_kwargs)
  File "C:\Users\bayro\AppData\Roaming\Python\Python310\site-packages\django\contrib\auth\decorators.py", line 60, in _view_wrapper
    return view_func(request, *args, **kwargs)
  File "C:\Users\bayro\Desktop\IngSoftware\career_roadmap\roadmap\views.py", line 70, in edit_profile
    return render(request, 'roadmap/edit_profile.html', {'form': form})
  File "C:\Users\bayro\AppData\Roaming\Python\Python310\site-packages\django\shortcuts.py", line 25, in render
    content = loader.render_to_string(template_name, context, request, using=using)
  File "C:\Users\bayro\AppData\Roaming\Python\Python310\site-packages\django\template\loader.py", line 61, in render_to_string
    template = get_template(template_name, using=using)
  File "C:\Users\bayro\AppData\Roaming\Python\Python310\site-packages\django\template\loader.py", line 19, in get_template
    raise TemplateDoesNotExist(template_name, chain=chain)
django.template.exceptions.TemplateDoesNotExist: roadmap/edit_profile.html
Internal Server Error: /roadmap/editar-perfil/
Traceback (most recent call last):
  File "C:\Users\bayro\AppData\Roaming\Python\Python310\site-packages\django\core\handlers\exception.py", line 55, in inner
    response = get_response(request)
  File "C:\Users\bayro\AppData\Roaming\Python\Python310\site-packages\django\core\handlers\base.py", line 197, in _get_response
    response = wrapped_callback(request, *callback_args, **callback_kwargs)
  File "C:\Users\bayro\AppData\Roaming\Python\Python310\site-packages\django\contrib\auth\decorators.py", line 60, in _view_wrapper
    return view_func(request, *args, **kwargs)
  File "C:\Users\bayro\Desktop\IngSoftware\career_roadmap\roadmap\views.py", line 70, in edit_profile
    return render(request, 'roadmap/edit_profile.html', {'form': form})
  File "C:\Users\bayro\AppData\Roaming\Python\Python310\site-packages\django\shortcuts.py", line 25, in render
    content = loader.render_to_string(template_name, context, request, using=using)
  File "C:\Users\bayro\AppData\Roaming\Python\Python310\site-packages\django\template\loader.py", line 61, in render_to_string
    template = get_template(template_name, using=using)
  File "C:\Users\bayro\AppData\Roaming\Python\Python310\site-packages\django\template\loader.py", line 19, in get_template
    raise TemplateDoesNotExist(template_name, chain=chain)
django.template.exceptions.TemplateDoesNotExist: roadmap/edit_profile.html
Internal Server Error: /roadmap/editar-perfil/
Traceback (most recent call last):
  File "C:\Users\bayro\AppData\Roaming\Python\Python310\site-packages\django\core\handlers\exception.py", line 55, in inner
    response = get_response(request)
  File "C:\Users\bayro\AppData\Roaming\Python\Python310\site-packages\django\core\handlers\base.py", line 197, in _get_response
    response = wrapped_callback(request, *callback_args, **callback_kwargs)
  File "C:\Users\bayro\AppData\Roaming\Python\Python310\site-packages\django\contrib\auth\decorators.py", line 60, in _view_wrapper
    return view_func(request, *args, **kwargs)
  File "C:\Users\bayro\Desktop\IngSoftware\career_roadmap\roadmap\views.py", line 67, in edit_profile
    return redirect('Home')  # Redirige a la vista del roadmap
  File "C:\Users\bayro\AppData\Roaming\Python\Python310\site-packages\django\shortcuts.py", line 49, in redirect
    return redirect_class(resolve_url(to, *args, **kwargs))
  File "C:\Users\bayro\AppData\Roaming\Python\Python310\site-packages\django\shortcuts.py", line 180, in resolve_url
    return reverse(to, args=args, kwargs=kwargs)
  File "C:\Users\bayro\AppData\Roaming\Python\Python310\site-packages\django\urls\base.py", line 88, in reverse
    return resolver._reverse_with_prefix(view, prefix, *args, **kwargs)
  File "C:\Users\bayro\AppData\Roaming\Python\Python310\site-packages\django\urls\resolvers.py", line 831, in _reverse_with_prefix
    raise NoReverseMatch(msg)
django.urls.exceptions.NoReverseMatch: Reverse for 'Home' not found. 'Home' is not a valid view function or pattern name.
Internal Server Error: /chat/
Traceback (most recent call last):
  File "C:\Users\bayro\AppData\Roaming\Python\Python310\site-packages\django\core\handlers\exception.py", line 55, in inner
    response = get_response(request)
  File "C:\Users\bayro\AppData\Roaming\Python\Python310\site-packages\django\core\handlers\base.py", line 197, in _get_response
    response = wrapped_callback(request, *callback_args, **callback_kwargs)
  File "C:\Users\bayro\AppData\Roaming\Python\Python310\site-packages\django\contrib\auth\decorators.py", line 60, in _view_wrapper
    return view_func(request, *args, **kwargs)
  File "C:\Users\bayro\Desktop\IngSoftware\career_roadmap\roadmap\views.py", line 19, in chat
    response = chatbot.get_response(user_input, chat_history)
  File "C:\Users\bayro\Desktop\IngSoftware\career_roadmap\roadmap\chatbot.py", line 25, in get_response
    response = self.generate_recommendation(chat_history)
TypeError: Chatbot.generate_recommendation() missing 1 required positional argument: 'chat_history'
Internal Server Error: /chat/
Traceback (most recent call last):
  File "C:\Users\bayro\AppData\Roaming\Python\Python310\site-packages\django\core\handlers\exception.py", line 55, in inner
    response = get_response(request)
  File "C:\Users\bayro\AppData\Roaming\Python\Python310\site-packages\django\core\handlers\base.py", line 197, in _get_response
    response = wrapped_callback(request, *callback_args, **callback_kwargs)
  File "C:\Users\bayro\AppData\Roaming\Python\Python310\site-packages\django\contrib\auth\decorators.py", line 60, in _view_wrapper
    return view_func(request, *args, **kwargs)
  File "C:\Users\bayro\Desktop\IngSoftware\career_roadmap\roadmap\views.py", line 19, in chat
    response = chatbot.get_response(user_input, chat_history)
  File "C:\Users\bayro\Desktop\IngSoftware\career_roadmap\roadmap\chatbot.py", line 25, in get_response
    response = self.generate_recommendation(chat_history)
TypeError: Chatbot.generate_recommendation() missing 1 required positional argument: 'chat_history'
Internal Server Error: /chat/
Traceback (most recent call last):
  File "C:\Users\bayro\AppData\Roaming\Python\Python310\site-packages\django\core\handlers\exception.py", line 55, in inner
    response = get_response(request)
  File "C:\Users\bayro\AppData\Roaming\Python\Python310\site-packages\django\core\handlers\base.py", line 197, in _get_response
    response = wrapped_callback(request, *callback_args, **callback_kwargs)
  File "C:\Users\bayro\AppData\Roaming\Python\Python310\site-packages\django\contrib\auth\decorators.py", line 60, in _view_wrapper
    return view_func(request, *args, **kwargs)
  File "C:\Users\bayro\Desktop\IngSoftware\career_roadmap\roadmap\views.py", line 19, in chat
    response = chatbot.get_response(user_input, chat_history)
  File "C:\Users\bayro\Desktop\IngSoftware\career_roadmap\roadmap\chatbot.py", line 25, in get_response
    response = self.generate_recommendation(chat_history)
TypeError: Chatbot.generate_recommendation() missing 1 required positional argument: 'chat_history'
Internal Server Error: /chat/
Traceback (most recent call last):
  File "C:\Users\bayro\AppData\Roaming\Python\Python310\site-packages\django\core\handlers\exception.py", line 55, in inner
    response = get_response(request)
  File "C:\Users\bayro\AppData\Roaming\Python\Python310\site-packages\django\core\handlers\base.py", line 197, in _get_response
    response = wrapped_callback(request, *callback_args, **callback_kwargs)
  File "C:\Users\bayro\AppData\Roaming\Python\Python310\site-packages\django\contrib\auth\decorators.py", line 60, in _view_wrapper
    return view_func(request, *args, **kwargs)
  File "C:\Users\bayro\Desktop\IngSoftware\career_roadmap\roadmap\views.py", line 19, in chat
    response = chatbot.get_response(user_input, chat_history)
  File "C:\Users\bayro\Desktop\IngSoftware\career_roadmap\roadmap\chatbot.py", line 25, in get_response
    response = self.generate_recommendation(chat_history)
TypeError: Chatbot.generate_recommendation() missing 1 required positional argument: 'chat_history'
